Workbook

Sheet Summary
A1: Customers & Brokers — Test Cases
A3: Page | B3: https://qa-crm.asquareab.com/customers (Customer and Broker Workspace)
A4: Build | B4: v1.0 1910-49
A5: Explored on | B5: 22/23-Oct-2026 (CRM Administrator, QA data)
A6: Scope | B6: Workspace cards and tabs; Customer Register (search, sort, paging, export, no manual create); Edit Customer (fields, sections, validation, saving, KYC upload / delete); Broker Register; Create / Edit Broker (validation, portal credentials); access control
A7: How to use | B7: Fill "Status" (Not Started / Pass / Fail / Blocked / Not Applicable) and "Remarks" on the Test Cases sheet; the counts below update automatically.
A8: Automation | B8: Every test case is automated in tests/customers-brokers/ ("Automated in" column); test names, steps and expected results come from this sheet. Run: npm run test:customers-brokers. lifecycle.spec.ts changes QA data on every run: it edits one customer's Remarks and puts them back, uploads a KYC PDF and deletes it, edits the test broker and restores it, and creates the test broker only if it does not exist yet (creating a broker also creates a broker portal login).
A9: Last run | B9: 22-Oct-2026 14:15, build v1.0 1910-49 — automated (tests/customers-brokers): 40 passed, 3 failed, 3 skipped (CB-040 only runs when a new broker is created; CB-044 and CB-045 by design). Defect report: reports/CRM_Defect_Report_2026-10-22_1415.xlsx
A11: By area | B11: Test cases | C11: High | D11: Pass | E11: Fail
A12: Workspace | B12: =COUNTIF('Test Cases'!$B$2:$B$46,A12) -> 5 | C12: =COUNTIFS('Test Cases'!$B$2:$B$46,A12,'Test Cases'!$K$2:$K$46,"High") -> 4 | D12: =COUNTIFS('Test Cases'!$B$2:$B$46,A12,'Test Cases'!$L$2:$L$46,"Pass") -> 5 | E12: =COUNTIFS('Test Cases'!$B$2:$B$46,A12,'Test Cases'!$L$2:$L$46,"Fail") -> 0
A13: Customer register | B13: =COUNTIF('Test Cases'!$B$2:$B$46,A13) -> 9 | C13: =COUNTIFS('Test Cases'!$B$2:$B$46,A13,'Test Cases'!$K$2:$K$46,"High") -> 5 | D13: =COUNTIFS('Test Cases'!$B$2:$B$46,A13,'Test Cases'!$L$2:$L$46,"Pass") -> 8 | E13: =COUNTIFS('Test Cases'!$B$2:$B$46,A13,'Test Cases'!$L$2:$L$46,"Fail") -> 1
A14: Customer detail | B14: =COUNTIF('Test Cases'!$B$2:$B$46,A14) -> 5 | C14: =COUNTIFS('Test Cases'!$B$2:$B$46,A14,'Test Cases'!$K$2:$K$46,"High") -> 2 | D14: =COUNTIFS('Test Cases'!$B$2:$B$46,A14,'Test Cases'!$L$2:$L$46,"Pass") -> 4 | E14: =COUNTIFS('Test Cases'!$B$2:$B$46,A14,'Test Cases'!$L$2:$L$46,"Fail") -> 1
A15: Customer edit | B15: =COUNTIF('Test Cases'!$B$2:$B$46,A15) -> 6 | C15: =COUNTIFS('Test Cases'!$B$2:$B$46,A15,'Test Cases'!$K$2:$K$46,"High") -> 4 | D15: =COUNTIFS('Test Cases'!$B$2:$B$46,A15,'Test Cases'!$L$2:$L$46,"Pass") -> 5 | E15: =COUNTIFS('Test Cases'!$B$2:$B$46,A15,'Test Cases'!$L$2:$L$46,"Fail") -> 1
A16: KYC | B16: =COUNTIF('Test Cases'!$B$2:$B$46,A16) -> 5 | C16: =COUNTIFS('Test Cases'!$B$2:$B$46,A16,'Test Cases'!$K$2:$K$46,"High") -> 3 | D16: =COUNTIFS('Test Cases'!$B$2:$B$46,A16,'Test Cases'!$L$2:$L$46,"Pass") -> 4 | E16: =COUNTIFS('Test Cases'!$B$2:$B$46,A16,'Test Cases'!$L$2:$L$46,"Fail") -> 0
A17: Broker register | B17: =COUNTIF('Test Cases'!$B$2:$B$46,A17) -> 4 | C17: =COUNTIFS('Test Cases'!$B$2:$B$46,A17,'Test Cases'!$K$2:$K$46,"High") -> 3 | D17: =COUNTIFS('Test Cases'!$B$2:$B$46,A17,'Test Cases'!$L$2:$L$46,"Pass") -> 4 | E17: =COUNTIFS('Test Cases'!$B$2:$B$46,A17,'Test Cases'!$L$2:$L$46,"Fail") -> 0
A18: Broker form | B18: =COUNTIF('Test Cases'!$B$2:$B$46,A18) -> 5 | C18: =COUNTIFS('Test Cases'!$B$2:$B$46,A18,'Test Cases'!$K$2:$K$46,"High") -> 4 | D18: =COUNTIFS('Test Cases'!$B$2:$B$46,A18,'Test Cases'!$L$2:$L$46,"Pass") -> 5 | E18: =COUNTIFS('Test Cases'!$B$2:$B$46,A18,'Test Cases'!$L$2:$L$46,"Fail") -> 0
A19: Broker save | B19: =COUNTIF('Test Cases'!$B$2:$B$46,A19) -> 3 | C19: =COUNTIFS('Test Cases'!$B$2:$B$46,A19,'Test Cases'!$K$2:$K$46,"High") -> 3 | D19: =COUNTIFS('Test Cases'!$B$2:$B$46,A19,'Test Cases'!$L$2:$L$46,"Pass") -> 3 | E19: =COUNTIFS('Test Cases'!$B$2:$B$46,A19,'Test Cases'!$L$2:$L$46,"Fail") -> 0
A20: Access | B20: =COUNTIF('Test Cases'!$B$2:$B$46,A20) -> 3 | C20: =COUNTIFS('Test Cases'!$B$2:$B$46,A20,'Test Cases'!$K$2:$K$46,"High") -> 3 | D20: =COUNTIFS('Test Cases'!$B$2:$B$46,A20,'Test Cases'!$L$2:$L$46,"Pass") -> 2 | E20: =COUNTIFS('Test Cases'!$B$2:$B$46,A20,'Test Cases'!$L$2:$L$46,"Fail") -> 0
A21: Total | B21: =SUM(B12:B20) -> 45 | C21: =SUM(C12:C20) -> 31 | D21: =SUM(D12:D20) -> 40 | E21: =SUM(E12:E20) -> 3
A23: By type | B23: Test cases
A24: Navigation | B24: =COUNTIF('Test Cases'!$J$2:$J$46,A24) -> 3
A25: UI | B25: =COUNTIF('Test Cases'!$J$2:$J$46,A25) -> 5
A26: Functional | B26: =COUNTIF('Test Cases'!$J$2:$J$46,A26) -> 17
A27: Negative | B27: =COUNTIF('Test Cases'!$J$2:$J$46,A27) -> 13
A28: Data | B28: =COUNTIF('Test Cases'!$J$2:$J$46,A28) -> 3
A29: Security | B29: =COUNTIF('Test Cases'!$J$2:$J$46,A29) -> 4
A31: By priority | B31: Test cases
A32: High | B32: =COUNTIF('Test Cases'!$K$2:$K$46,A32) -> 31
A33: Medium | B33: =COUNTIF('Test Cases'!$K$2:$K$46,A33) -> 14
A34: Low | B34: =COUNTIF('Test Cases'!$K$2:$K$46,A34) -> 0
A36: Execution status | B36: Test cases
A37: Not Started | B37: =COUNTIF('Test Cases'!$L$2:$L$46,A37) -> 0
A38: Pass | B38: =COUNTIF('Test Cases'!$L$2:$L$46,A38) -> 40
A39: Fail | B39: =COUNTIF('Test Cases'!$L$2:$L$46,A39) -> 3
A40: Blocked | B40: =COUNTIF('Test Cases'!$L$2:$L$46,A40) -> 2
A41: Not Applicable | B41: =COUNTIF('Test Cases'!$L$2:$L$46,A41) -> 0
A43: Observations | B43: =COUNTA(Observations!$A$2:$A9) -> 8

Sheet Test Cases
A1: TC ID | B1: Area | C1: Component | D1: Test Case | E1: Preconditions | F1: Test Steps | G1: Test Data | H1: Expected Result | I1: Observed (automated run, build v1.0 1910-49) | J1: Type | K1: Priority | L1: Status | M1: Remarks | N1: Automated in
A2: CB-001 | B2: Workspace | C2: Navigation | D2: Customers & Brokers opens from the side menu | E2: Logged in as CRM Administrator | F2: 1. Open Home / Dashboard (/) 2. Click "Customers & Brokers" in the main menu | H2: URL is /customers; eyebrow "CUSTOMERS & BROKERS", heading "Customer and Broker Workspace"; the Customers tab is selected | I2: As expected | J2: Navigation | K2: High | L2: Pass | N2: tests/customers-brokers/workspace.spec.ts
A3: CB-002 | B3: Workspace | C3: Cards | D3: Cards show loaded values | E3: Logged in as CRM Administrator | F3: 1. Open /customers 2. Read Customers, Brokers, Active Customers, Active Brokers | H3: Every card shows a number; Active Customers ≤ Customers and Active Brokers ≤ Brokers | I3: As expected | J3: UI | K3: High | L3: Pass | N3: tests/customers-brokers/workspace.spec.ts
A4: CB-003 | B4: Workspace | C4: Cards | D4: Customers and Brokers cards equal their registers | E4: Logged in as CRM Administrator | F4: 1. Open /customers; read the pager of the Customer Register 2. Click Brokers; read the Broker Register total | H4: Customers card = Customer Register total; Brokers card = Broker Register total | I4: As expected | J4: Data | K4: High | L4: Pass | N4: tests/customers-brokers/workspace.spec.ts
A5: CB-004 | B5: Workspace | C5: Cards | D5: Active cards count the active records | E5: Logged in as CRM Administrator | F5: 1. Open /customers; Export the Customer Register 2. Count customers with status Active in the file 3. Count ACTIVE brokers in the Broker Register | H5: Active Customers = customers with status Active (not Prospect); Active Brokers = brokers with status ACTIVE | I5: As expected | J5: Data | K5: High | L5: Pass | N5: tests/customers-brokers/workspace.spec.ts
A6: CB-005 | B6: Workspace | C6: Tabs | D6: Tabs switch between the registers | E6: Logged in as CRM Administrator | F6: 1. Open /customers 2. Click Brokers, then Customers | H6: Brokers shows "Broker Register" with New Broker and the Brokers tab highlighted; Customers shows "Customer Register" again; the URL stays /customers | I6: As expected | J6: Navigation | K6: Medium | L6: Pass | N6: tests/customers-brokers/workspace.spec.ts
A7: CB-006 | B7: Customer register | C7: Register | D7: Customer Register loads and shows every column | E7: Logged in as CRM Administrator | F7: 1. Open /customers 2. Check the columns and rows 3. Check the console and network log | H7: Columns Customer, Contact, Buyer Type, Project, Status, Created Date; each row shows a name with its CUST-… code, phone and email; no JavaScript errors, failed API calls, NaN or undefined | I7: As expected | J7: UI | K7: High | L7: Pass | N7: tests/customers-brokers/customers.spec.ts
A8: CB-007 | B8: Customer register | C8: Register | D8: Pagination covers every customer | E8: Logged in as CRM Administrator | F8: 1. Open /customers; read "Showing 1–20 of N customers · Page 1 of M" 2. Sort by Created Date oldest first and page to the end | H8: N = Customers card; the last page ends at N and Next is disabled; N rows in all, none repeated | I8: As expected | J8: Functional | K8: High | L8: Pass | N8: tests/customers-brokers/customers.spec.ts
A9: CB-008 | B9: Customer register | C9: Search | D9: Search by name, code, phone and email | E9: Logged in as CRM Administrator | F9: 1. Open /customers 2. Search the 2nd row's name, then its CUST code, phone (typed without spaces) and email | G9: 2nd row of the register | H9: Each search lists that customer, and every row matches the term | I9: As expected when the phone is typed without spaces; with the spaces shown on screen nothing is found (OBS-04) | J9: Functional | K9: High | L9: Pass | N9: tests/customers-brokers/customers.spec.ts
A10: CB-009 | B10: Customer register | C10: Search | D10: Search with no match shows an empty register | E10: Logged in as CRM Administrator | F10: 1. Open /customers 2. Search a term that matches nothing | G10: "zz-no-such-customer-<timestamp>" | H10: No rows, an empty-state message, and Export disabled | I10: No rows and no message at all — the table is simply empty (OBS-02) | J10: Negative | K10: Medium | L10: Fail | N10: tests/customers-brokers/customers.spec.ts
A11: CB-010 | B11: Customer register | C11: Search | D11: Clearing the search restores the register | E11: Logged in as CRM Administrator | F11: 1. Open /customers; note the total 2. Search a customer 3. Click the clear (×) button | G11: Name of the first row | H11: The box is empty and the total and page 1 are as before | I11: As expected | J11: Functional | K11: Medium | L11: Pass | N11: tests/customers-brokers/customers.spec.ts
A12: CB-011 | B12: Customer register | C12: Sort | D12: Sort by Customer and Created Date | E12: Logged in as CRM Administrator | F12: 1. Open /customers 2. Check the default order 3. Sort Customer ascending, then descending 4. Sort Created Date ascending | H12: Default is newest first (Created Date ▼); Customer sorts alphabetically both ways; ascending Created Date gives oldest first | I12: As expected | J12: Functional | K12: Medium | L12: Pass | N12: tests/customers-brokers/customers.spec.ts
A13: CB-012 | B13: Customer register | C13: Export | D13: Export downloads the Customer Register | E13: Logged in as CRM Administrator | F13: 1. Open /customers 2. Click Export 3. Open the file | H13: File "customers-<today>.xlsx" with columns Customer Code, ERP Customer ID, Name, Mobile, WhatsApp, Email, City, Nationality, Country, Buyer Type, Funding Source, Preferred Communication, Default Currency, Default Project, Status, Created At, and one row per customer (= Customers card) | I13: As expected | J13: Functional | K13: High | L13: Pass | N13: tests/customers-brokers/customers.spec.ts
A14: CB-013 | B14: Customer register | C14: Export | D14: Export follows the search | E14: Logged in as CRM Administrator | F14: 1. Open /customers 2. Search the 2nd row's name 3. Click Export | G14: Name of the 2nd row | H14: The file holds exactly the customers listed for the search | I14: As expected | J14: Functional | K14: Medium | L14: Pass | N14: tests/customers-brokers/customers.spec.ts
A15: CB-014 | B15: Customer register | C15: Create | D15: Customers cannot be created by hand | E15: Logged in as CRM Administrator | F15: 1. Open /customers 2. Look at New Customer | H15: New Customer is disabled with the tooltip "Customers are created automatically through Lead qualification and conversion. Direct manual customer creation is disabled." | I15: As expected | J15: Negative | K15: High | L15: Pass | N15: tests/customers-brokers/customers.spec.ts
A16: CB-015 | B16: Customer detail | C16: Edit Customer | D16: Opening a customer shows its details | E16: Logged in as CRM Administrator | F16: 1. Open /customers 2. Click the first CUST code 3. Compare the form with the row and GET /customers/<id> | H16: Edit Customer shows the same display name, mobile, email and buyer type as the row and the record; Created and Updated are shown; opening it changes nothing | I16: As expected | J16: Functional | K16: High | L16: Pass | N16: tests/customers-brokers/customers.spec.ts
A17: CB-016 | B17: Customer detail | C17: Edit Customer | D17: Customer detail shows every section | E17: Logged in as CRM Administrator | F17: 1. Open a customer 2. Scroll through the window | H17: Sections All Units, Agreed Packs, Payments & statement, Documents & KYC (with a "KYC: …" status), Communications and History | I17: As expected | J17: UI | K17: Medium | L17: Pass | N17: tests/customers-brokers/customers.spec.ts
A18: CB-017 | B18: Customer detail | C18: All Units | D18: All Units lists the customer's opportunities | E18: Logged in as CRM Administrator | F18: 1. Open a customer that has an opportunity 2. Compare All Units with the customer's opportunities (GET /customers/<id>/units) | G18: First customer with an OPP in All Units | H18: Every opportunity of the customer is listed with its number, stage and lead | I18: As expected | J18: Data | K18: Medium | L18: Pass | N18: tests/customers-brokers/customers.spec.ts
A19: CB-018 | B19: Customer detail | C19: Edit Customer | D19: Record link (?selected=id) opens and keeps the customer open | E19: Logged in as CRM Administrator | F19: 1. Copy a row's link (/customers?selected=<id>) 2. Open it 3. Wait 3 seconds | H19: That customer's window opens and stays open | I19: As expected | J19: Navigation | K19: High | L19: Pass | N19: tests/customers-brokers/customers.spec.ts
A20: CB-019 | B20: Customer detail | C20: Edit Customer | D20: Link to a missing customer shows a message | E20: Logged in as CRM Administrator | F20: 1. Open /customers?selected=<id that does not exist> | G20: 00000000-0000-0000-0000-000000000000 | H20: A message says the customer was not found | I20: No "not found" message appears (OBS-03) | J20: Negative | K20: Medium | L20: Fail | N20: tests/customers-brokers/customers.spec.ts
A21: CB-020 | B21: Customer edit | C21: Validation | D21: Mobile is required | E21: Logged in as CRM Administrator; a customer whose name has letters only (first one in the register) | F21: 1. Open the customer 2. Clear Mobile 3. Click Update Customer | G21: Mobile empty | H21: "Required Fields Missing — Mobile"; nothing is saved | I21: As expected | J21: Negative | K21: High | L21: Pass | N21: tests/customers-brokers/customers.spec.ts
A22: CB-021 | B22: Customer edit | C22: Validation | D22: Names may only contain letters | E22: Logged in as CRM Administrator; a customer whose name has letters only (first one in the register) | F22: 1. Open the customer 2. Type a digit into First Name 3. Click Update Customer | G22: First Name "Daniel2" | H22: "First Name may contain letters, spaces, apostrophes, and hyphens only."; nothing is saved | I22: As expected | J22: Negative | K22: High | L22: Pass | N22: tests/customers-brokers/customers.spec.ts
A23: CB-022 | B23: Customer edit | C23: Validation | D23: An invalid email is refused | E23: Logged in as CRM Administrator; a customer whose name has letters only (first one in the register) | F23: 1. Open the customer 2. Type "bad-email" in Email 3. Click Update Customer | G23: Email "bad-email" | H23: A message asks for a valid email; nothing is saved | I23: Nothing saved; only the browser's own email check appears, no app message (OBS-07) | J23: Negative | K23: Medium | L23: Pass | N23: tests/customers-brokers/customers.spec.ts
A24: CB-023 | B24: Customer edit | C24: Edit Customer | D24: Closing without saving discards changes | E24: Logged in as CRM Administrator; a customer whose name has letters only (first one in the register) | F24: 1. Open the customer 2. Change Remarks 3. Click Close, then Keep editing 4. Click Close, then Discard 5. Open the customer again | G24: Remarks + " [unsaved]" | H24: "Discard changes? — You have unsaved changes in this form. Close it and discard them?"; Keep editing keeps the change; Discard closes the window; nothing is sent and the original remarks are shown again | I24: As expected | J24: Negative | K24: Medium | L24: Pass | N24: tests/customers-brokers/customers.spec.ts
A25: CB-024 | B25: Customer edit | C25: Edit Customer | D25: Editing a customer saves the change | E25: Logged in as CRM Administrator; a customer whose name has letters only (first one in the register) | F25: 1. Open the customer; add " [automated test edit]" to Remarks 2. Click Update Customer 3. Open the customer again; read Remarks, Updated and History 4. Afterwards the test puts the original remarks back | G25: Remarks + " [automated test edit]" | H25: PATCH succeeds and the window closes; reopened, the remarks show the change, Updated moves on and History lists the remarks change; the original text is restored afterwards | I25: Saved; the window closes with no confirmation message (OBS-05); original remarks restored | J25: Functional | K25: High | L25: Pass | N25: tests/customers-brokers/lifecycle.spec.ts
A26: CB-025 | B26: Customer edit | C26: Edit Customer | D26: A customer created from a lead can be edited | E26: Logged in as CRM Administrator; a customer created automatically from a lead whose name has digits (e.g. "Enquiry LD-2026-0467 — UAE Prospect 467") | F26: 1. Open the customer 2. Change only Remarks 3. Click Update Customer 4. Afterwards the test puts the original remarks back | G26: Remarks + " [automated test edit]" | H26: The change is saved — the name the system gave the customer must not block other edits | I26: Refused: "Invalid Entry — First Name / Last Name / Display Name may contain letters, spaces, apostrophes, and hyphens only." — the name the system gave the customer blocks every edit (OBS-01) | J26: Functional | K26: High | L26: Fail | N26: tests/customers-brokers/lifecycle.spec.ts
A27: CB-026 | B27: KYC | C27: Upload | D27: KYC upload validation | E27: Logged in as CRM Administrator; a customer whose name has letters only (first one in the register) | F27: 1. Open the customer 2. Click Upload with nothing chosen 3. Choose Passport and click Upload | H27: "Choose the document type." then "Enter the Passport number."; nothing is uploaded | I27: As expected | J27: Negative | K27: High | L27: Pass | N27: tests/customers-brokers/lifecycle.spec.ts
A28: CB-027 | B28: KYC | C28: Upload | D28: KYC accepts only PDF, JPG or PNG | E28: Logged in as CRM Administrator; a customer whose name has letters only (first one in the register) | F28: 1. Open the customer 2. Choose Passport, a number, an expiry and a .txt file 3. Click Upload | G28: notes.txt | H28: The file is refused with a message; nothing is uploaded | I28: As expected | J28: Negative | K28: Medium | L28: Pass | N28: tests/customers-brokers/lifecycle.spec.ts
A29: CB-028 | B29: KYC | C29: Upload | D29: Uploading a KYC document | E29: Logged in as CRM Administrator; a customer whose name has letters only (first one in the register) | F29: 1. Open the customer 2. Passport, number AUTOTEST-<time>, expiry next month 15th, a PDF 3. Click Upload | G29: kyc-passport.pdf | H29: The document is listed as "Passport · <number>", "Expires <date>", file name and size, "Pending review", with Verify, Reject and Delete; KYC status becomes "Under Review" | I29: As expected | J29: Functional | K29: High | L29: Pass | N29: tests/customers-brokers/lifecycle.spec.ts
A30: CB-029 | B30: KYC | C30: Delete | D30: Deleting a KYC document | E30: Logged in as CRM Administrator; the document uploaded by CB-028 | F30: 1. Click Delete on the document, then Keep 2. Click Delete again, then Delete | H30: "Delete KYC document? … Keep / Delete"; Keep leaves it; Delete removes it and KYC goes back to "Not Started" | I30: As expected | J30: Functional | K30: High | L30: Pass | N30: tests/customers-brokers/lifecycle.spec.ts
A31: CB-030 | B31: Broker register | C31: Register | D31: Broker Register loads and shows every column | E31: Logged in as CRM Administrator | F31: 1. Open /customers › Brokers 2. Check the columns and rows | H31: Columns Broker, Contact, City, Plan, Status, Created Date; each row shows a name with its BRK-… code, phone and email | I31: As expected | J31: UI | K31: High | L31: Pass | N31: tests/customers-brokers/brokers.spec.ts
A32: CB-031 | B32: Broker register | C32: Search | D32: Search brokers by name, phone and email | E32: Logged in as CRM Administrator | F32: 1. Open Brokers 2. Search the first broker's name, phone and email 3. Search a term that matches nothing | G32: First broker of the register | H32: Each search lists that broker; a term with no match shows no rows | I32: As expected when the phone is typed without spaces (OBS-04) | J32: Functional | K32: High | L32: Pass | N32: tests/customers-brokers/brokers.spec.ts
A33: CB-032 | B33: Broker register | C33: Sort | D33: Sort brokers by name and Created Date | E33: Logged in as CRM Administrator | F33: 1. Open Brokers 2. Check the default order 3. Sort Broker ascending, then descending | H33: Default is newest first (Created Date ▼); Broker sorts alphabetically both ways | I33: As expected | J33: Functional | K33: Medium | L33: Pass | N33: tests/customers-brokers/brokers.spec.ts
A34: CB-033 | B34: Broker register | C34: Edit Broker | D34: Opening a broker shows its details | E34: Logged in as CRM Administrator | F34: 1. Open Brokers 2. Click the first broker | H34: Edit Broker shows the same name, mobile, email, city and commission plan as the row | I34: As expected | J34: Functional | K34: High | L34: Pass | N34: tests/customers-brokers/brokers.spec.ts
A35: CB-034 | B35: Broker form | C35: Create Broker | D35: New Broker opens the form | E35: Logged in as CRM Administrator | F35: 1. Open Brokers 2. Click New Broker | H35: Form "Create Broker" with Broker Name (required), Registration No, Tax ID, Mobile, Email, Country, City, Commission Plan / %, Preferred Communication and Remarks | I35: As expected | J35: UI | K35: High | L35: Pass | N35: tests/customers-brokers/brokers.spec.ts
A36: CB-035 | B36: Broker form | C36: Validation | D36: Broker Name is required | E36: Logged in as CRM Administrator | F36: 1. Open New Broker 2. Click Create without filling anything | H36: "Broker Name is required."; nothing is saved | I36: As expected | J36: Negative | K36: High | L36: Pass | N36: tests/customers-brokers/brokers.spec.ts
A37: CB-036 | B37: Broker form | C37: Validation | D37: An invalid broker email is refused | E37: Logged in as CRM Administrator | F37: 1. Open New Broker 2. Enter a name and "not-an-email" as Email 3. Click Create | G37: Email "not-an-email" | H37: "Email must be a valid email address (e.g. name@example.com)."; nothing is saved | I37: As expected | J37: Negative | K37: High | L37: Pass | N37: tests/customers-brokers/brokers.spec.ts
A38: CB-037 | B38: Broker form | C38: Validation | D38: Commission must be between 0 and 100 | E38: Logged in as CRM Administrator | F38: 1. Open New Broker 2. Enter a name and 150% as Commission Plan / % 3. Click Create | G38: Commission "150%" | H38: "Commission must be a number between 0 and 100 (percent)."; nothing is saved | I38: As expected | J38: Negative | K38: High | L38: Pass | N38: tests/customers-brokers/brokers.spec.ts
A39: CB-038 | B39: Broker form | C39: Create Broker | D39: Closing the form creates nothing | E39: Logged in as CRM Administrator | F39: 1. Open New Broker 2. Enter a name 3. Click Close, then Keep editing 4. Click Close, then Discard | G39: Name "Automated test - not saved" | H39: "Discard changes?" is asked; Keep editing keeps the name; Discard closes the form; nothing is sent and the Brokers card is unchanged | I39: As expected | J39: Negative | K39: Medium | L39: Pass | N39: tests/customers-brokers/brokers.spec.ts
A40: CB-039 | B40: Broker save | C40: Create Broker | D40: Creating a broker (one test broker, reused) | E40: Logged in as CRM Administrator | F40: 1. Search Brokers for "Automated test broker" 2. If none: New Broker › name, mobile, email, commission 2, remarks › Create 3. Check the register and the Brokers card | G40: Name "Automated test broker <date-time>" | H40: If created: POST succeeds, the broker is listed ACTIVE with its BRK code and values, Brokers +1. If it already exists, the existing test broker is checked instead (no new broker, so no new portal login) | I40: The test broker already existed (created on 22-Oct-2026 during exploration), so it was reused — no new broker or portal login | J40: Functional | K40: High | L40: Pass | N40: tests/customers-brokers/lifecycle.spec.ts
...

Sheet Observations
A1: Obs ID | B1: Area | C1: Observation | D1: Expected / Question | E1: Suggested severity | F1: Related TC
A2: OBS-01 | B2: Customer edit | C2: Customers created automatically from a lead get names such as "Enquiry LD-2026-0467 — UAE Prospect 467", which the Edit Customer form itself rejects ("First / Last / Display Name may contain letters, spaces, apostrophes, and hyphens only"). Any change to these customers — even Remarks — is refused. | D2: Either give lead-created customers valid names, or only validate the name fields when they are changed. | E2: High | F2: CB-025
A3: OBS-02 | B3: Customer register | C3: A search with no match shows an empty table with no message (the Opportunities register says "No opportunities found."). | D3: Show a short empty-state message. | E3: Low | F3: CB-009
A4: OBS-03 | B4: Customer detail | C4: A link to a customer that does not exist (/customers?selected=<unknown id>) shows no "not found" message. | D4: Tell the user the customer was not found or is not accessible. | E4: Medium | F4: CB-019
A5: OBS-04 | B5: Search | C5: Searching a phone number as it is displayed (with spaces, e.g. "+254 700 000 000") finds nothing in either register; it only matches when typed without spaces. | D5: Ignore spaces in phone searches. | E5: Low | F5: CB-008, CB-031
A6: OBS-05 | B6: Customer edit | C6: Update Customer closes the window without any confirmation message. | D6: Show a short "Customer updated" notice. | E6: Low | F6: CB-024
A7: OBS-06 | B7: Broker create | C7: Creating a broker automatically creates a Broker Portal login (username = broker code, temporary password shown once). | D7: Information: the test suite therefore creates its test broker only once and reuses it. | E7: Info | F7: CB-039, CB-040
A8: OBS-07 | B8: Customer edit | C8: An invalid customer email is blocked only by the browser's built-in check (a browser tooltip); the app shows no message of its own, unlike the broker form. | D8: Show the same inline message as the broker form. | E8: Low | F8: CB-022
A9: OBS-08 | B9: Broker register | C9: The Broker Register has no Export button, while the Customer Register has one. | D9: Question: should brokers be exportable too? | E9: Low | F9: CB-030
