Workbook

Sheet Summary
A1: Lead Reports — Test Cases
A3: Page | B3: https://qa-crm.asquareab.com/reports/leads
A4: Build | B4: v1.0 0510-44
A5: Explored on | B5: 13-Oct-2026 (CRM Administrator, QA data)
A6: Scope | B6: Header filters and views, 5 tabs, every KPI card, chart, table, count link, drill-down list and export
A7: How to use | B7: Fill "Status" (Pass / Fail / Blocked / Not Applicable) and "Remarks" on the Test Cases sheet; counts below update automatically.
A8: Note | B8: "Observed" values were read from QA on the exploration date; data changes over time, so re-read figures when executing. Drill-down links were executed on 13-Oct-2026 (Status = Pass on those test cases).
A10: By tab | B10: Test cases | C10: High | D10: Pass | E10: Fail
A11: General | B11: =COUNTIF('Test Cases'!$B$2:$B$167,A11) | C11: =COUNTIFS('Test Cases'!$B$2:$B$167,A11,'Test Cases'!$K$2:$K$167,"High") | D11: =COUNTIFS('Test Cases'!$B$2:$B$167,A11,'Test Cases'!$L$2:$L$167,"Pass") | E11: =COUNTIFS('Test Cases'!$B$2:$B$167,A11,'Test Cases'!$L$2:$L$167,"Fail")
A12: Tabs | B12: =COUNTIF('Test Cases'!$B$2:$B$167,A12) | C12: =COUNTIFS('Test Cases'!$B$2:$B$167,A12,'Test Cases'!$K$2:$K$167,"High") | D12: =COUNTIFS('Test Cases'!$B$2:$B$167,A12,'Test Cases'!$L$2:$L$167,"Pass") | E12: =COUNTIFS('Test Cases'!$B$2:$B$167,A12,'Test Cases'!$L$2:$L$167,"Fail")
A13: Filters | B13: =COUNTIF('Test Cases'!$B$2:$B$167,A13) | C13: =COUNTIFS('Test Cases'!$B$2:$B$167,A13,'Test Cases'!$K$2:$K$167,"High") | D13: =COUNTIFS('Test Cases'!$B$2:$B$167,A13,'Test Cases'!$L$2:$L$167,"Pass") | E13: =COUNTIFS('Test Cases'!$B$2:$B$167,A13,'Test Cases'!$L$2:$L$167,"Fail")
A14: Views | B14: =COUNTIF('Test Cases'!$B$2:$B$167,A14) | C14: =COUNTIFS('Test Cases'!$B$2:$B$167,A14,'Test Cases'!$K$2:$K$167,"High") | D14: =COUNTIFS('Test Cases'!$B$2:$B$167,A14,'Test Cases'!$L$2:$L$167,"Pass") | E14: =COUNTIFS('Test Cases'!$B$2:$B$167,A14,'Test Cases'!$L$2:$L$167,"Fail")
A15: Overview & Funnel | B15: =COUNTIF('Test Cases'!$B$2:$B$167,A15) | C15: =COUNTIFS('Test Cases'!$B$2:$B$167,A15,'Test Cases'!$K$2:$K$167,"High") | D15: =COUNTIFS('Test Cases'!$B$2:$B$167,A15,'Test Cases'!$L$2:$L$167,"Pass") | E15: =COUNTIFS('Test Cases'!$B$2:$B$167,A15,'Test Cases'!$L$2:$L$167,"Fail")
A16: Drill-down list | B16: =COUNTIF('Test Cases'!$B$2:$B$167,A16) | C16: =COUNTIFS('Test Cases'!$B$2:$B$167,A16,'Test Cases'!$K$2:$K$167,"High") | D16: =COUNTIFS('Test Cases'!$B$2:$B$167,A16,'Test Cases'!$L$2:$L$167,"Pass") | E16: =COUNTIFS('Test Cases'!$B$2:$B$167,A16,'Test Cases'!$L$2:$L$167,"Fail")
A17: Source & Channel | B17: =COUNTIF('Test Cases'!$B$2:$B$167,A17) | C17: =COUNTIFS('Test Cases'!$B$2:$B$167,A17,'Test Cases'!$K$2:$K$167,"High") | D17: =COUNTIFS('Test Cases'!$B$2:$B$167,A17,'Test Cases'!$L$2:$L$167,"Pass") | E17: =COUNTIFS('Test Cases'!$B$2:$B$167,A17,'Test Cases'!$L$2:$L$167,"Fail")
A18: Aging & Follow-up | B18: =COUNTIF('Test Cases'!$B$2:$B$167,A18) | C18: =COUNTIFS('Test Cases'!$B$2:$B$167,A18,'Test Cases'!$K$2:$K$167,"High") | D18: =COUNTIFS('Test Cases'!$B$2:$B$167,A18,'Test Cases'!$L$2:$L$167,"Pass") | E18: =COUNTIFS('Test Cases'!$B$2:$B$167,A18,'Test Cases'!$L$2:$L$167,"Fail")
A19: Qualification & Conversion | B19: =COUNTIF('Test Cases'!$B$2:$B$167,A19) | C19: =COUNTIFS('Test Cases'!$B$2:$B$167,A19,'Test Cases'!$K$2:$K$167,"High") | D19: =COUNTIFS('Test Cases'!$B$2:$B$167,A19,'Test Cases'!$L$2:$L$167,"Pass") | E19: =COUNTIFS('Test Cases'!$B$2:$B$167,A19,'Test Cases'!$L$2:$L$167,"Fail")
A20: Salesperson Scorecard | B20: =COUNTIF('Test Cases'!$B$2:$B$167,A20) | C20: =COUNTIFS('Test Cases'!$B$2:$B$167,A20,'Test Cases'!$K$2:$K$167,"High") | D20: =COUNTIFS('Test Cases'!$B$2:$B$167,A20,'Test Cases'!$L$2:$L$167,"Pass") | E20: =COUNTIFS('Test Cases'!$B$2:$B$167,A20,'Test Cases'!$L$2:$L$167,"Fail")
A21: Cross-page & non-functional | B21: =COUNTIF('Test Cases'!$B$2:$B$167,A21) | C21: =COUNTIFS('Test Cases'!$B$2:$B$167,A21,'Test Cases'!$K$2:$K$167,"High") | D21: =COUNTIFS('Test Cases'!$B$2:$B$167,A21,'Test Cases'!$L$2:$L$167,"Pass") | E21: =COUNTIFS('Test Cases'!$B$2:$B$167,A21,'Test Cases'!$L$2:$L$167,"Fail")
A22: Total | B22: =SUM(B11:B21) | C22: =SUM(C11:C21) | D22: =SUM(D11:D21) | E22: =SUM(E11:E21)
A24: By type | B24: Test cases
A25: Navigation | B25: =COUNTIF('Test Cases'!$J$2:$J$167,A25)
A26: Security | B26: =COUNTIF('Test Cases'!$J$2:$J$167,A26)
A27: Non-functional | B27: =COUNTIF('Test Cases'!$J$2:$J$167,A27)
A28: UI | B28: =COUNTIF('Test Cases'!$J$2:$J$167,A28)
A29: Negative | B29: =COUNTIF('Test Cases'!$J$2:$J$167,A29)
A30: Functional | B30: =COUNTIF('Test Cases'!$J$2:$J$167,A30)
A31: Accessibility | B31: =COUNTIF('Test Cases'!$J$2:$J$167,A31)
A32: Data | B32: =COUNTIF('Test Cases'!$J$2:$J$167,A32)
A34: By priority | B34: Test cases
A35: High | B35: =COUNTIF('Test Cases'!$K$2:$K$167,A35)
A36: Medium | B36: =COUNTIF('Test Cases'!$K$2:$K$167,A36)
A37: Low | B37: =COUNTIF('Test Cases'!$K$2:$K$167,A37)
A39: Execution status | B39: Test cases
A40: Not Started | B40: =COUNTIF('Test Cases'!$L$2:$L$167,A40)
A41: Pass | B41: =COUNTIF('Test Cases'!$L$2:$L$167,A41)
A42: Fail | B42: =COUNTIF('Test Cases'!$L$2:$L$167,A42)
A43: Blocked | B43: =COUNTIF('Test Cases'!$L$2:$L$167,A43)
A44: Not Applicable | B44: =COUNTIF('Test Cases'!$L$2:$L$167,A44)
A46: Observations | B46: =COUNTA(Observations!$A$2:$A$13)
...

Sheet Test Cases
A1: TC ID | B1: Tab | C1: Component | D1: Test Case | E1: Preconditions | F1: Test Steps | G1: Test Data | H1: Expected Result | I1: Observed (13-Oct-2026, build v1.0 0510-44) | J1: Type | K1: Priority | L1: Status | M1: Remarks
A2: LR-001 | B2: General | C2: Navigation | D2: Open Lead Reports from the Reports & Analytics hub card | E2: Logged in as CRM Administrator | F2: 1. Open /reports-analytics 2. Click the "Lead Reports" card (LIVE) | H2: URL is /reports/leads; heading "Lead Reports"; intro "Funnel, source, aging, qualification and conversion…"; Overview & Funnel tab is active | I2: As expected | J2: Navigation | K2: High | L2: Not Started
A3: LR-002 | B3: General | C3: Navigation | D3: Open Lead Reports directly by URL | E3: Logged in as CRM Administrator | F3: 1. Enter https://qa-crm.asquareab.com/reports/leads in the browser | H3: Page loads with all KPI cards, Lead Funnel, Data Completeness and 12-Month Trend; no error | I3: As expected | J3: Navigation | K3: High | L3: Not Started
A4: LR-003 | B4: General | C4: Breadcrumb | D4: "REPORTS & ANALYTICS" breadcrumb returns to the hub | E4: Logged in as CRM Administrator; Lead Reports open (https://qa-crm.asquareab.com/reports/leads) | F4: 1. Click "REPORTS & ANALYTICS" above the page heading | H4: Reports & Analytics hub (/reports-analytics) opens | I4: As expected | J4: Navigation | K4: Medium | L4: Not Started
A5: LR-004 | B5: General | C5: Security | D5: Lead Reports requires a login | E5: Not logged in | F5: 1. Log out (or open a private window) 2. Open https://qa-crm.asquareab.com/reports/leads | H5: User is redirected to the login page; no report data is shown | I5: Covered by automated test RA-085 | J5: Security | K5: High | L5: Not Started
A6: LR-005 | B6: General | C6: Page load | D6: Page loads without errors or broken values | E6: Logged in as CRM Administrator; Lead Reports open (https://qa-crm.asquareab.com/reports/leads) | F6: 1. Open Lead Reports with DevTools (Console, Network) open | H6: No JavaScript errors; no failed API calls; no NaN / undefined / blank values | I6: As expected | J6: Non-functional | K6: High | L6: Not Started
A7: LR-006 | B7: General | C7: Help | D7: "How these numbers are calculated" explains every measure | E7: Logged in as CRM Administrator; Lead Reports open (https://qa-crm.asquareab.com/reports/leads) | F7: 1. Click "How these numbers are calculated" | H7: Definitions shown for Leads captured, Contacted, Qualified, Opportunity, Reserved, SPA Signed, Won Value, Lost, Open, Idle days, the "now" figures and the View rules | I7: Expands with all definitions; states that Aging and "now" figures ignore the period | J7: UI | K7: Low | L7: Not Started
A8: LR-007 | B8: Tabs | C8: Tab bar | D8: Overview & Funnel is the default tab | E8: Logged in as CRM Administrator; Lead Reports open (https://qa-crm.asquareab.com/reports/leads) | F8: 1. Open Lead Reports | H8: Tab bar shows 5 tabs; "Overview & Funnel" is highlighted | I8: As expected | J8: UI | K8: Medium | L8: Not Started
A9: LR-008 | B9: Tabs | C9: Tab bar | D9: Open the "Source & Channel" tab | E9: Logged in as CRM Administrator; Lead Reports open (https://qa-crm.asquareab.com/reports/leads) | F9: 1. Click "Source & Channel" | H9: URL becomes ?tab=source; tab is highlighted; its sections load (API /reports/leads/breakdown) | I9: As expected | J9: Navigation | K9: High | L9: Not Started
A10: LR-009 | B10: Tabs | C10: Tab bar | D10: Open the "Aging & Follow-up" tab | E10: Logged in as CRM Administrator; Lead Reports open (https://qa-crm.asquareab.com/reports/leads) | F10: 1. Click "Aging & Follow-up" | H10: URL becomes ?tab=aging; tab is highlighted; its sections load (API /reports/leads/aging) | I10: As expected | J10: Navigation | K10: High | L10: Not Started
A11: LR-010 | B11: Tabs | C11: Tab bar | D11: Open the "Qualification & Conversion" tab | E11: Logged in as CRM Administrator; Lead Reports open (https://qa-crm.asquareab.com/reports/leads) | F11: 1. Click "Qualification & Conversion" | H11: URL becomes ?tab=qualification; tab is highlighted; its sections load (API /reports/leads/qualification) | I11: As expected | J11: Navigation | K11: High | L11: Not Started
A12: LR-011 | B12: Tabs | C12: Tab bar | D12: Open the "Salesperson Scorecard" tab | E12: Logged in as CRM Administrator; Lead Reports open (https://qa-crm.asquareab.com/reports/leads) | F12: 1. Click "Salesperson Scorecard" | H12: URL becomes ?tab=scorecard; tab is highlighted; its sections load (API /reports/leads/scorecard) | I12: As expected | J12: Navigation | K12: High | L12: Not Started
A13: LR-012 | B13: Tabs | C13: Tab URL | D13: A tab opens directly from its URL | E13: Logged in as CRM Administrator; Lead Reports open (https://qa-crm.asquareab.com/reports/leads) | F13: 1. Open https://qa-crm.asquareab.com/reports/leads?tab=aging | H13: Aging & Follow-up tab is active and loaded | I13: As expected | J13: Navigation | K13: Medium | L13: Not Started
... A18: LR-017 | B18: Filters | C18: Period | D18: Default period is "This month" | E18: Logged in as CRM Administrator; Lead Reports open (https://qa-crm.asquareab.com/reports/leads) | F18: 1. Open Lead Reports 2. Read the Period dropdown | H18: "This month" is selected (same period as the hub and dashboard) | I18: "Last 12 months" is selected (see Observations OBS-01) | J18: Functional | K18: High | L18: Not Started
A19: LR-018 | B19: Filters | C19: Period | D19: Each period reloads the report | E19: Logged in as CRM Administrator; Lead Reports open (https://qa-crm.asquareab.com/reports/leads) | F19: 1. Select each period in turn (except Custom dates) | G19: This month, Last month, This quarter, Last quarter, Year to date, Last 12 months | H19: KPIs, funnel and tables reload for that period (API ?period=<value>); values are valid | I19: This month → Leads Captured 16, Contact Rate 50%, SPA Signed 1, Won Value 1.23M USD | J19: Functional | K19: High | L19: Not Started
A20: LR-019 | B20: Filters | C20: Custom dates | D20: Custom dates shows From and To | E20: Logged in as CRM Administrator; Lead Reports open (https://qa-crm.asquareab.com/reports/leads) | F20: 1. Select Period = Custom dates | H20: From and To date fields appear | I20: As expected (no min/max limits on the fields) | J20: UI | K20: Medium | L20: Not Started
A21: LR-020 | B21: Filters | C21: Custom dates | D21: A valid custom range reloads the report | E21: Logged in as CRM Administrator; Lead Reports open (https://qa-crm.asquareab.com/reports/leads) | F21: 1. Custom dates 2. From = 01-Sep-2026, To = 30-Sep-2026 | G21: 2026-09-01 → 2026-09-30 | H21: Report reloads for that range (API period=custom&from=…&to=…) | I21: As expected | J21: Functional | K21: High | L21: Not Started
A22: LR-021 | B22: Filters | C22: Custom dates | D22: From later than To is rejected with a message | E22: Logged in as CRM Administrator; Lead Reports open (https://qa-crm.asquareab.com/reports/leads) | F22: 1. Custom dates 2. From = 30-Sep-2026, To = 01-Sep-2026 | G22: 2026-09-30 → 2026-09-01 | H22: A validation message is shown and the report is not reloaded with an invalid range | I22: No message; no request sent; the old figures stay on screen (OBS-02) | J22: Negative | K22: Medium | L22: Not Started
A23: LR-022 | B23: Filters | C23: Custom dates | D23: A range with no data shows zeros | E23: Logged in as CRM Administrator; Lead Reports open (https://qa-crm.asquareab.com/reports/leads) | F23: 1. Custom dates 01-Jan-2030 → 31-Jan-2030 | G23: 2030-01-01 → 2030-01-31 | H23: Leads Captured 0, SPA Signed 0, Won Value 0 USD, rates "—"; funnel 0; "now" figures (Open Leads Now) unchanged | I23: As expected (Open Leads Now stays 364 — it is "as of today") | J23: Negative | K23: Medium | L23: Not Started
A24: LR-023 | B24: Filters | C24: Project | D24: "Project" filter narrows the report | E24: Logged in as CRM Administrator; Lead Reports open (https://qa-crm.asquareab.com/reports/leads) | F24: 1. Note Leads Captured 2. Select Project = Palm Exotjca Limited | G24: Project = Palm Exotjca Limited | H24: Dropdown starts with "All projects"; after selecting, every KPI, funnel step and table reloads for that project only; counts ≤ unfiltered | I24: To verify | J24: Functional | K24: Medium | L24: Not Started
A25: LR-024 | B25: Filters | C25: Lead Source | D25: "Lead Source" filter narrows the report | E25: Logged in as CRM Administrator; Lead Reports open (https://qa-crm.asquareab.com/reports/leads) | F25: 1. Note Leads Captured 2. Select Lead Source = Digital Marketing | G25: Lead Source = Digital Marketing | H25: Dropdown starts with "All sources"; after selecting, every KPI, funnel step and table reloads for that lead source only; counts ≤ unfiltered | I25: Digital Marketing → Leads Captured 18, Contact Rate 77.8%, SPA Signed 5, Won Value 6.27M USD, Open Leads Now 7 | J25: Functional | K25: High | L25: Not Started
A26: LR-025 | B26: Filters | C26: Capture Channel | D26: "Capture Channel" filter narrows the report | E26: Logged in as CRM Administrator; Lead Reports open (https://qa-crm.asquareab.com/reports/leads) | F26: 1. Note Leads Captured 2. Select Capture Channel = Google Ads | G26: Capture Channel = Google Ads | H26: Dropdown starts with "All channels"; after selecting, every KPI, funnel step and table reloads for that capture channel only; counts ≤ unfiltered | I26: To verify | J26: Functional | K26: Medium | L26: Not Started
A27: LR-026 | B27: Filters | C27: Campaign | D27: "Campaign" filter narrows the report | E27: Logged in as CRM Administrator; Lead Reports open (https://qa-crm.asquareab.com/reports/leads) | F27: 1. Note Leads Captured 2. Select Campaign = Palm Exotica Campaign 2026-06 | G27: Campaign = Palm Exotica Campaign 2026-06 | H27: Dropdown starts with "All campaigns"; after selecting, every KPI, funnel step and table reloads for that campaign only; counts ≤ unfiltered | I27: To verify | J27: Functional | K27: Medium | L27: Not Started
A28: LR-027 | B28: Filters | C28: Broker | D28: "Broker" filter narrows the report | E28: Logged in as CRM Administrator; Lead Reports open (https://qa-crm.asquareab.com/reports/leads) | F28: 1. Note Leads Captured 2. Select Broker = Palm Exotica Broker 1 | G28: Broker = Palm Exotica Broker 1 | H28: Dropdown starts with "All brokers"; after selecting, every KPI, funnel step and table reloads for that broker only; counts ≤ unfiltered | I28: To verify | J28: Functional | K28: Medium | L28: Not Started
A29: LR-028 | B29: Filters | C29: Salesperson | D29: "Salesperson" filter narrows the report | E29: Logged in as CRM Administrator; Lead Reports open (https://qa-crm.asquareab.com/reports/leads) | F29: 1. Note Leads Captured 2. Select Salesperson = Mahalakshmi | G29: Salesperson = Mahalakshmi | H29: Dropdown starts with "All salespeople"; after selecting, every KPI, funnel step and table reloads for that salesperson only; counts ≤ unfiltered | I29: Options list "Mahalakshmi" twice (OBS-06) | J29: Functional | K29: High | L29: Not Started
A30: LR-029 | B30: Filters | C30: Prospect Type | D30: "Prospect Type" filter narrows the report | E30: Logged in as CRM Administrator; Lead Reports open (https://qa-crm.asquareab.com/reports/leads) | F30: 1. Note Leads Captured 2. Select Prospect Type = Individual (Person) | G30: Prospect Type = Individual (Person) | H30: Dropdown starts with "All types"; after selecting, every KPI, funnel step and table reloads for that prospect type only; counts ≤ unfiltered | I30: To verify | J30: Functional | K30: Medium | L30: Not Started
A31: LR-030 | B31: Filters | C31: Nationality | D31: "Nationality" filter narrows the report | E31: Logged in as CRM Administrator; Lead Reports open (https://qa-crm.asquareab.com/reports/leads) | F31: 1. Note Leads Captured 2. Select Nationality = India | G31: Nationality = India | H31: Dropdown starts with "All nationalities"; after selecting, every KPI, funnel step and table reloads for that nationality only; counts ≤ unfiltered | I31: To verify | J31: Functional | K31: Medium | L31: Not Started
A32: LR-031 | B32: Filters | C32: Filters | D32: Several filters combine (AND) | E32: Logged in as CRM Administrator; Lead Reports open (https://qa-crm.asquareab.com/reports/leads) | F32: 1. Lead Source = Digital Marketing 2. Project = Palm Exotjca Limited | G32: Digital Marketing + Palm Exotjca Limited | H32: Results match both filters; counts ≤ either filter alone | I32: To verify | J32: Functional | K32: Medium | L32: Not Started
A33: LR-032 | B33: Filters | C33: Filters | D33: Filters apply to every tab | E33: Logged in as CRM Administrator; Lead Reports open (https://qa-crm.asquareab.com/reports/leads) | F33: 1. Lead Source = Digital Marketing on Overview 2. Open Source & Channel | H33: The filter stays selected and the Source & Channel table shows only Digital Marketing (18 leads) | I33: As expected | J33: Functional | K33: High | L33: Not Started
A34: LR-033 | B34: Filters | C34: Filters | D34: Filters after a page reload | E34: Logged in as CRM Administrator; Lead Reports open (https://qa-crm.asquareab.com/reports/leads) | F34: 1. Select Lead Source = Digital Marketing 2. Press F5 | H34: Agreed behaviour: filters reset to defaults and the figures match the defaults (filters are not kept in the URL) | I34: Filters reset to defaults; tab is kept (OBS-05) | J34: Functional | K34: Low | L34: Not Started
A35: LR-034 | B35: Filters | C35: Reset filters | D35: Reset filters restores the defaults | E35: Logged in as CRM Administrator; Lead Reports open (https://qa-crm.asquareab.com/reports/leads) | F35: 1. Change Lead Source and Project 2. Click Reset filters | H35: Reset is disabled until a filter changes; after Reset every dropdown returns to its default and the KPIs return to the original values | I35: As expected (Leads Captured back to 613) | J35: Functional | K35: High | L35: Not Started
A36: LR-035 | B36: Filters | C36: Filters | D36: Drill-down lists respect the filters | E36: Logged in as CRM Administrator; Lead Reports open (https://qa-crm.asquareab.com/reports/leads) | F36: 1. Lead Source = Digital Marketing 2. Click the Leads Captured count | H36: Drill-down lists 18 leads, all with Source = Digital Marketing | I36: Clicked 18 = header 18 = 18 rows; export 18 rows; no duplicates (verification #179); all 18 rows Source = Digital Marketing | J36: Functional | K36: High | L36: Pass | M36: Executed 13-Oct-2026 (scripted check, see Drill-down Verification)
A37: LR-036 | B37: Views | C37: View | D37: View buttons All / You and your team / Mine | E37: Logged in as CRM Administrator; Lead Reports open (https://qa-crm.asquareab.com/reports/leads) | F37: 1. Look at the view buttons | H37: Three buttons; "All" active for a user with the Reports approve right | I37: As expected (Admin opens on All) | J37: UI | K37: Medium | L37: Not Started
A38: LR-037 | B38: Views | C38: View | D38: "You and your team" shows the user's reporting line | E38: Logged in as CRM Administrator; Lead Reports open (https://qa-crm.asquareab.com/reports/leads) | F38: 1. Click "You and your team" | H38: Report reloads with view=team; counts ≤ All | I38: Leads Captured 597 (All 613) | J38: Functional | K38: High | L38: Not Started
A39: LR-038 | B39: Views | C39: View | D39: "Mine" shows only the user's own leads | E39: Logged in as CRM Administrator; Lead Reports open (https://qa-crm.asquareab.com/reports/leads) | F39: 1. Click "Mine" | H39: Report reloads with view=self; counts ≤ You and your team | I39: Leads Captured 597 (same as team for Admin) | J39: Functional | K39: High | L39: Not Started
A40: LR-039 | B40: Views | C40: View | D40: "All" restores every salesperson | E40: Logged in as CRM Administrator; Lead Reports open (https://qa-crm.asquareab.com/reports/leads) | F40: 1. Click Mine 2. Click All | H40: Figures return to the All values | I40: As expected | J40: Functional | K40: Medium | L40: Not Started
A41: LR-040 | B41: Views | C41: View | D41: Default view depends on the role | E41: Manager and salesperson test accounts | F41: 1. Log in as a manager → open Lead Reports 2. Log in as a salesperson → open Lead Reports | H41: Manager opens on "You and your team"; salesperson opens on "Mine" (per the help text) | I41: Needs manager and salesperson accounts | J41: Security | K41: Medium | L41: Not Started
A42: LR-041 | B42: Views | C42: View | D42: Salesperson's Mine view shows a team average on the scorecard | E42: Salesperson test account | F42: 1. Log in as a salesperson 2. Salesperson Scorecard tab | H42: A team-average row is shown next to the user's own row | I42: Needs a salesperson account | J42: Functional | K42: Low | L42: Not Started
A43: LR-042 | B43: Overview & Funnel | C43: KPI cards | D43: All 8 KPI cards are shown | E43: Logged in as CRM Administrator; Lead Reports open (https://qa-crm.asquareab.com/reports/leads) | F43: 1. Open Overview & Funnel | H43: Leads Captured, Contact Rate, Qualification Rate, Opportunity Conversion, SPA Signed, Won Value, Avg Time to First Contact, Open Leads Now — each with a value and a subtitle | I43: As expected | J43: UI | K43: High | L43: Not Started
A44: LR-043 | B44: Overview & Funnel | C44: Leads Captured | D44: Leads Captured count opens its leads | E44: Logged in as CRM Administrator; Lead Reports open (https://qa-crm.asquareab.com/reports/leads) | F44: 1. Click the Leads Captured value (613) | G44: Last 12 months | H44: Drill-down "Leads captured" opens with 613 leads | I44: Clicked 613 = header 613; 500 rows shown + "showing the first 500"; export 613 rows; no duplicates (verification #1) | J44: Functional | K44: High | L44: Pass | M44: Executed 13-Oct-2026 (scripted check, see Drill-down Verification)
...

Sheet Drill-down Verification
A1: # | B1: Tab | C1: Count link (where) | D1: Clicked count | E1: Header count | F1: Rows listed | G1: "showing the first 500" | H1: Export rows | I1: Duplicate leads | J1: Bucket | K1: Row rule checked | L1: Rows breaking rule | M1: Grouping check (rows outside the clicked row) | N1: Result | O1: Notes
A2: 1 | B2: Overview & Funnel | C2: KPI "Leads Captured" | D2: 613 | E2: 613 | F2: 500 | G2: Yes | H2: 613 | I2: 0 | J2: captured | K2: Captured date present | L2: 0 | M2: n/a | N2: Pass
A3: 2 | B3: Overview & Funnel | C3: KPI "SPA Signed" | D3: 76 | E3: 76 | F3: 76 | H3: 76 | I3: 0 | J3: won | K3: Won Value > 0 | L3: 0 | M3: n/a | N3: Pass
A4: 3 | B4: Overview & Funnel | C4: KPI "Open Leads Now" | D4: 364 | E4: 364 | F4: 364 | H4: 364 | I4: 0 | J4: openNow | K4: Open status (not Converted/Lost/Disqualified/Duplicate) | L4: 0 | M4: n/a | N4: Pass
A5: 4 | B5: Overview & Funnel | C5: KPI "Open Leads Now" (subtitle link) | D5: 342 | E5: 342 | F5: 342 | H5: 342 | I5: 0 | J5: idleNow | K5: Open status and Idle > 30 d | L5: 0 | M5: n/a | N5: Pass
A6: 5 | B6: Overview & Funnel | C6: KPI "Open Leads Now" (subtitle link) | D6: 163 | E6: 163 | F6: 163 | H6: 163 | I6: 0 | J6: neverContactedNow | K6: Open status and no First Contact | L6: 0 | M6: n/a | N6: Pass
A7: 6 | B7: Overview & Funnel | C7: Funnel "Captured" | D7: 613 | E7: 613 | F7: 500 | G7: Yes | H7: 613 | I7: 0 | K7: (no row rule) | L7: 0 | M7: n/a | N7: Pass
A8: 7 | B8: Overview & Funnel | C8: Funnel "Contacted" | D8: 322 | E8: 322 | F8: 322 | H8: 322 | I8: 0 | J8: contacted | K8: First Contact date present, or status Contacted or later (page definition) | L8: 0 | M8: n/a | N8: Pass | O8: 71 rows break "First Contact date present"
A9: 8 | B9: Overview & Funnel | C9: Funnel "Qualified" | D9: 249 | E9: 249 | F9: 249 | H9: 249 | I9: 0 | J9: qualified | K9: Qualified date present | L9: 0 | M9: n/a | N9: Pass
A10: 9 | B10: Overview & Funnel | C10: Funnel "Opportunity" | D10: 121 | E10: 121 | F10: 121 | H10: 121 | I10: 0 | J10: converted | K10: Status Converted / Opportunity Created | L10: 0 | M10: n/a | N10: Pass
A11: 10 | B11: Overview & Funnel | C11: Funnel "Reserved" | D11: 106 | E11: 106 | F11: 106 | H11: 106 | I11: 0 | J11: reserved | K11: Status Converted / Opportunity Created (reservation not shown in list) | L11: 0 | M11: n/a | N11: Pass
A12: 11 | B12: Overview & Funnel | C12: Funnel "SPA Signed" | D12: 76 | E12: 76 | F12: 76 | H12: 76 | I12: 0 | J12: won | K12: Won Value > 0 | L12: 0 | M12: n/a | N12: Pass
A13: 12 | B13: Source & Channel | C13: Performance by Lead Source › Unspecified › Leads | D13: 572 | E13: 572 | F13: 500 | G13: Yes | H13: 572 | I13: 0 | J13: captured | K13: Captured date present | L13: 0 | M13: 0 | N13: Pass
A14: 13 | B14: Source & Channel | C14: Performance by Lead Source › Unspecified › Contacted | D14: 290 | E14: 290 | F14: 290 | H14: 290 | I14: 0 | J14: contacted | K14: First Contact date present, or status Contacted or later (page definition) | L14: 0 | M14: 0 | N14: Pass | O14: 71 rows break "First Contact date present"
A15: 14 | B15: Source & Channel | C15: Performance by Lead Source › Unspecified › Qualified | D15: 218 | E15: 218 | F15: 218 | H15: 218 | I15: 0 | J15: qualified | K15: Qualified date present | L15: 0 | M15: 0 | N15: Pass
A16: 15 | B16: Source & Channel | C16: Performance by Lead Source › Unspecified › Opportunity | D16: 92 | E16: 92 | F16: 92 | H16: 92 | I16: 0 | J16: converted | K16: Status Converted / Opportunity Created | L16: 0 | M16: 0 | N16: Pass
A17: 16 | B17: Source & Channel | C17: Performance by Lead Source › Unspecified › Reserved | D17: 89 | E17: 89 | F17: 89 | H17: 89 | I17: 0 | J17: reserved | K17: Status Converted / Opportunity Created (reservation not shown in list) | L17: 0 | M17: 0 | N17: Pass
A18: 17 | B18: Source & Channel | C18: Performance by Lead Source › Unspecified › SPA Signed | D18: 66 | E18: 66 | F18: 66 | H18: 66 | I18: 0 | J18: won | K18: Won Value > 0 | L18: 0 | M18: 0 | N18: Pass
A19: 18 | B19: Source & Channel | C19: Performance by Lead Source › Unspecified › Lost | D19: 128 | E19: 128 | F19: 128 | H19: 128 | I19: 0 | J19: lost | K19: Status Lost / Disqualified | L19: 0 | M19: 0 | N19: Pass
A20: 19 | B20: Source & Channel | C20: Performance by Lead Source › Digital Marketing › Leads | D20: 18 | E20: 18 | F20: 18 | H20: 18 | I20: 0 | J20: captured | K20: Captured date present | L20: 0 | M20: 0 | N20: Pass
A21: 20 | B21: Source & Channel | C21: Performance by Lead Source › Digital Marketing › Contacted | D21: 14 | E21: 14 | F21: 14 | H21: 14 | I21: 0 | J21: contacted | K21: First Contact date present | L21: 0 | M21: 0 | N21: Pass
A22: 21 | B22: Source & Channel | C22: Performance by Lead Source › Digital Marketing › Qualified | D22: 13 | E22: 13 | F22: 13 | H22: 13 | I22: 0 | J22: qualified | K22: Qualified date present | L22: 0 | M22: 0 | N22: Pass
A23: 22 | B23: Source & Channel | C23: Performance by Lead Source › Digital Marketing › Opportunity | D23: 11 | E23: 11 | F23: 11 | H23: 11 | I23: 0 | J23: converted | K23: Status Converted / Opportunity Created | L23: 0 | M23: 0 | N23: Pass
A24: 23 | B24: Source & Channel | C24: Performance by Lead Source › Digital Marketing › Reserved | D24: 7 | E24: 7 | F24: 7 | H24: 7 | I24: 0 | J24: reserved | K24: Status Converted / Opportunity Created (reservation not shown in list) | L24: 0 | M24: 0 | N24: Pass
A25: 24 | B25: Source & Channel | C25: Performance by Lead Source › Digital Marketing › SPA Signed | D25: 5 | E25: 5 | F25: 5 | H25: 5 | I25: 0 | J25: won | K25: Won Value > 0 | L25: 0 | M25: 0 | N25: Pass
A26: 25 | B26: Source & Channel | C26: Performance by Lead Source › Broker Channels › Leads | D26: 6 | E26: 6 | F26: 6 | H26: 6 | I26: 0 | J26: captured | K26: Captured date present | L26: 0 | M26: 0 | N26: Pass
... A62: 61 | B62: Source & Channel | C62: Performance by Lead Source › Referrals › Opportunity | D62: 1 | E62: 1 | F62: 1 | H62: 1 | I62: 0 | J62: converted | K62: Status Converted / Opportunity Created | L62: 0 | M62: 0 | N62: Pass
A63: 62 | B63: Source & Channel (Capture Channel) | C63: Performance by Capture Channel › Unspecified › Leads | D63: 587 | E63: 587 | F63: 500 | G63: Yes | H63: 587 | I63: 0 | J63: captured | K63: Captured date present | L63: 0 | M63: 0 | N63: Pass
A64: 63 | B64: Source & Channel (Capture Channel) | C64: Performance by Capture Channel › Google Ads › Leads | D64: 5 | E64: 5 | F64: 5 | H64: 5 | I64: 0 | J64: captured | K64: Captured date present | L64: 0 | M64: 0 | N64: Pass
A65: 64 | B65: Source & Channel (Capture Channel) | C65: Performance by Capture Channel › WhatsApp › Leads | D65: 5 | E65: 5 | F65: 5 | H65: 5 | I65: 0 | J65: captured | K65: Captured date present | L65: 0 | M65: 0 | N65: Pass
A66: 65 | B66: Source & Channel (Capture Channel) | C66: Performance by Capture Channel › Google Search › Leads | D66: 3 | E66: 3 | F66: 3 | H66: 3 | I66: 0 | J66: captured | K66: Captured date present | L66: 0 | M66: 0 | N66: Pass
A67: 66 | B67: Source & Channel (Capture Channel) | C67: Performance by Capture Channel › Hotel Guest Referral › Leads | D67: 2 | E67: 2 | F67: 2 | H67: 2 | I67: 0 | J67: captured | K67: Captured date present | L67: 0 | M67: 0 | N67: Pass
A68: 67 | B68: Source & Channel (Capture Channel) | C68: Performance by Capture Channel › International Broker › Leads | D68: 2 | E68: 2 | F68: 2 | H68: 2 | I68: 0 | J68: captured | K68: Captured date present | L68: 0 | M68: 0 | N68: Pass
A69: 68 | B69: Source & Channel (Capture Channel) | C69: Performance by Capture Channel › Property Finder › Leads | D69: 2 | E69: 2 | F69: 2 | H69: 2 | I69: 0 | J69: captured | K69: Captured date present | L69: 0 | M69: 0 | N69: Pass
A70: 69 | B70: Source & Channel (Capture Channel) | C70: Performance by Capture Channel › Bank Referral › Leads | D70: 1 | E70: 1 | F70: 1 | H70: 1 | I70: 0 | J70: captured | K70: Captured date present | L70: 0 | M70: 0 | N70: Pass
A71: 70 | B71: Source & Channel (Capture Channel) | C71: Performance by Capture Channel › Email Inquiry › Leads | D71: 1 | E71: 1 | F71: 1 | H71: 1 | I71: 0 | J71: captured | K71: Captured date present | L71: 0 | M71: 0 | N71: Pass
A72: 71 | B72: Source & Channel (Capture Channel) | C72: Performance by Capture Channel › Landing Page › Leads | D72: 1 | E72: 1 | F72: 1 | H72: 1 | I72: 0 | J72: captured | K72: Captured date present | L72: 0 | M72: 0 | N72: Pass
A73: 72 | B73: Source & Channel (Capture Channel) | C73: Performance by Capture Channel › Mortgage Provider › Leads | D73: 1 | E73: 1 | F73: 1 | H73: 1 | I73: 0 | J73: captured | K73: Captured date present | L73: 0 | M73: 0 | N73: Pass
A74: 73 | B74: Source & Channel (Capture Channel) | C74: Performance by Capture Channel › Property Exhibition › Leads | D74: 1 | E74: 1 | F74: 1 | H74: 1 | I74: 0 | J74: captured | K74: Captured date present | L74: 0 | M74: 0 | N74: Pass
A75: 74 | B75: Source & Channel (Capture Channel) | C75: Performance by Capture Channel › Real Estate Agency › Leads | D75: 1 | E75: 1 | F75: 1 | H75: 1 | I75: 0 | J75: captured | K75: Captured date present | L75: 0 | M75: 0 | N75: Pass
...

Sheet Clickable Map
A1: Tab | B1: Component | C1: Element | D1: Clickable | E1: What happens | F1: API called
A2: All | B2: Header | C2: REPORTS & ANALYTICS breadcrumb | D2: Yes | E2: Opens /reports-analytics | F2: —
A3: All | B3: Header | C3: 9 filter dropdowns (Period, Project, Lead Source, Capture Channel, Campaign, Broker, Salesperson, Prospect Type, Nationality) | D3: Yes | E3: Reloads the current tab for the selection; carried to every tab; reset on page reload | F3: …?period=…&<filter>RefId=…
A4: All | B4: Header | C4: Custom dates From / To | D4: Yes | E4: Reloads when both are valid; From > To is ignored silently | F4: period=custom&from=…&to=…
A5: All | B5: Header | C5: View: All / You and your team / Mine | D5: Yes | E5: Reloads with the view | F5: view=all | team | self
A6: All | B6: Header | C6: Reset filters | D6: Yes (disabled until a change) | E6: Restores all dropdowns | F6: —
A7: All | B7: Header | C7: How these numbers are calculated | D7: Yes | E7: Expands the definitions | F7: —
A8: All | B8: Tab bar | C8: 5 tabs | D8: Yes | E8: Switch tab; URL ?tab=source|aging|qualification|scorecard; closes any drill-down | F8: overview | breakdown | aging | qualification | scorecard
A9: Overview & Funnel | B9: KPI cards | C9: Leads Captured value | D9: Yes | E9: Drill-down "Leads captured" (first 500 shown) (verified 13-Oct-2026) | F9: drill?bucket=captured
A10: Overview & Funnel | B10: KPI cards | C10: SPA Signed value | D10: Yes | E10: Drill-down "Leads with a signed SPA" (verified 13-Oct-2026) | F10: drill?bucket=won
A11: Overview & Funnel | B11: KPI cards | C11: Open Leads Now value / idle / never contacted | D11: Yes (3 links) | E11: Drill-downs "Open leads (today)", "…idle over 30 days", "…never contacted" (as of today) (verified 13-Oct-2026) | F11: drill?bucket=openNow | idleNow | neverContactedNow
A12: Overview & Funnel | B12: KPI cards | C12: Contact Rate, Qualification Rate, Opportunity Conversion, Won Value, Avg Time to First Contact | D12: No | E12: — | F12: —
... A33: Drill-down list | B33: Panel | C33: Close | D33: Yes | E33: Closes the list (Esc does not) | F33: —

Sheet Observations
A1: Obs ID | B1: Area | C1: Observation | D1: Expected / Question | E1: Suggested severity | F1: Related TC
A2: OBS-01 | B2: Filters | C2: The page opens on "Last 12 months". | D2: Should open on "This month" like the hub and dashboard (workbook scenario RA-013). | E2: Medium | F2: LR-017
A3: OBS-02 | B3: Custom dates | C3: From later than To: nothing happens — no message, no reload, old figures remain. | D3: Show a validation message (or swap / block the dates). | E3: Medium | F3: LR-021
A4: OBS-03 | B4: Drill-down | C4: Esc does not close the drill-down list; only the Close button does. | D4: Esc should close it (keyboard accessibility). | E4: Low | F4: LR-074
A5: OBS-04 | B5: Source & Channel / Qualification | C5: Rating and Score tables (Qualification & Conversion) have no drill-down links, unlike the other tables. Correction: Lost counts on Source & Channel ARE clickable when above 0 — zero counts are plain text everywhere. | D5: Confirm whether the Rating / Score counts should open drill-downs for consistency. | E5: Low | F5: LR-125
A6: OBS-05 | B6: Filters | C6: Filters are not kept in the URL and reset on reload (the tab is kept). | D6: Confirm intended; a filtered view cannot be shared or bookmarked. | E6: Low | F6: LR-033
A7: OBS-06 | B7: Filters | C7: Salesperson dropdown lists "Mahalakshmi" twice (two users with the same name). | D7: Show something that tells them apart (e.g. email). | E7: Low | F7: LR-028
A8: OBS-07 | B8: Drill-down | C8: Lists over 500 leads show only the first 500 ("showing the first 500"). | D8: Confirm the Export contains all leads (see test case). | E8: Info
A9: OBS-08 | B9: Exports | C9: Export headers differ from the screen ("Qualification %" vs "Qual. %", "Avg Hours to Contact" vs "Avg First Contact", "Won Value (Base)"); breakdown export has no Total row; scorecard export has extra columns (Reserved, Lost, Overdue Follow-ups). | D9: Confirm intended; align names if users compare file and screen. | E9: Low | F9: LR-100, LR-138
A10: OBS-09 | B10: Qualification & Conversion | C10: Avg First Contact mixes hours and days ("46.4 h", "85.9 d"). | D10: Use consistent units or make the unit obvious. | E10: Low | F10: LR-121
A11: OBS-10 | B11: Data quality | C11: 572 of 613 leads have no Lead Source ("Unspecified"); Data Completeness shows Lead source recorded 6.7%. | D11: Data issue in QA; help text says Lead Source is now mandatory on new leads. | E11: Info | F11: LR-091
A12: OBS-11 | B12: Tabs | C12: Browser Back after switching tabs returned to Overview & Funnel instead of the previous tab. | D12: Confirm intended navigation history. | E12: Low
A13: OBS-12 | B13: Tables | C13: Table column headers are not sortable on any tab. | D13: Confirm intended. | E13: Info | F13: LR-102
A14: OBS-13 | B14: Drill-down / data | C14: 71 leads with status "Contacted" have no First Contact date: the Contacted list and export show "—" in First Contact. They are counted as contacted through the status change and are correctly not in "Never contacted". | D14: Record the status-change date as the first contact (or show it), so the list explains why each lead counts as contacted. | E14: Low | F14: LR-058, LR-078
