Workbook

Sheet Summary
A1: Unit Reservations — Test Cases
A3: Page | B3: https://qa-crm.asquareab.com/reservations
A4: Build | B4: v1.0 1910-49
A5: Explored on | B5: 21/22-Oct-2026 (CRM Administrator, QA data)
A6: Scope | B6: Status cards and Amount, Pending My Approval, Reservation Register (search, sort, paging), Reservation Detail (facts, workflow, history, documents), New Reservation form and unit picker, create, replace, approve (ERP sync), cancel, and access control
A7: How to use | B7: Fill "Status" (Not Started / Pass / Fail / Blocked / Not Applicable) and "Remarks" on the Test Cases sheet; the counts below update automatically.
A8: Automation | B8: Every test case is automated in tests/reservations/ ("Automated in" column); test names, steps and expected results come from this sheet. Run: npm run test:reservations. lifecycle.spec.ts changes QA data on every run: it converts one Ready to Convert lead, takes it to Reservation Ready, creates, replaces, approves (ERP sync is sent) and cancels a reservation, so the units are released at the end.
A9: Last run | B9: 22-Oct-2026 10:52 full run (reports/CRM_Defect_Report_2026-10-22_1052.xlsx), then the read-only specs again after fixing two test-timing issues (UR-007, UR-017): 54 passed, 11 failed, 4 blocked (skipped by design).
A11: By area | B11: Test cases | C11: High | D11: Pass | E11: Fail
A12: List & cards | B12: =COUNTIF('Test Cases'!$B$2:$B$70,A12) -> 8 | C12: =COUNTIFS('Test Cases'!$B$2:$B$70,A12,'Test Cases'!$K$2:$K$70,"High") -> 7 | D12: =COUNTIFS('Test Cases'!$B$2:$B$70,A12,'Test Cases'!$L$2:$L$70,"Pass") -> 7 | E12: =COUNTIFS('Test Cases'!$B$2:$B$70,A12,'Test Cases'!$L$2:$L$70,"Fail") -> 1
A13: Search & sort | B13: =COUNTIF('Test Cases'!$B$2:$B$70,A13) -> 8 | C13: =COUNTIFS('Test Cases'!$B$2:$B$70,A13,'Test Cases'!$K$2:$K$70,"High") -> 2 | D13: =COUNTIFS('Test Cases'!$B$2:$B$70,A13,'Test Cases'!$L$2:$L$70,"Pass") -> 7 | E13: =COUNTIFS('Test Cases'!$B$2:$B$70,A13,'Test Cases'!$L$2:$L$70,"Fail") -> 1
A14: Detail | B14: =COUNTIF('Test Cases'!$B$2:$B$70,A14) -> 8 | C14: =COUNTIFS('Test Cases'!$B$2:$B$70,A14,'Test Cases'!$K$2:$K$70,"High") -> 5 | D14: =COUNTIFS('Test Cases'!$B$2:$B$70,A14,'Test Cases'!$L$2:$L$70,"Pass") -> 7 | E14: =COUNTIFS('Test Cases'!$B$2:$B$70,A14,'Test Cases'!$L$2:$L$70,"Fail") -> 1
A15: Create form | B15: =COUNTIF('Test Cases'!$B$2:$B$70,A15) -> 6 | C15: =COUNTIFS('Test Cases'!$B$2:$B$70,A15,'Test Cases'!$K$2:$K$70,"High") -> 4 | D15: =COUNTIFS('Test Cases'!$B$2:$B$70,A15,'Test Cases'!$L$2:$L$70,"Pass") -> 6 | E15: =COUNTIFS('Test Cases'!$B$2:$B$70,A15,'Test Cases'!$L$2:$L$70,"Fail") -> 0
A16: Create | B16: =COUNTIF('Test Cases'!$B$2:$B$70,A16) -> 8 | C16: =COUNTIFS('Test Cases'!$B$2:$B$70,A16,'Test Cases'!$K$2:$K$70,"High") -> 7 | D16: =COUNTIFS('Test Cases'!$B$2:$B$70,A16,'Test Cases'!$L$2:$L$70,"Pass") -> 7 | E16: =COUNTIFS('Test Cases'!$B$2:$B$70,A16,'Test Cases'!$L$2:$L$70,"Fail") -> 1
A17: Documents | B17: =COUNTIF('Test Cases'!$B$2:$B$70,A17) -> 3 | C17: =COUNTIFS('Test Cases'!$B$2:$B$70,A17,'Test Cases'!$K$2:$K$70,"High") -> 1 | D17: =COUNTIFS('Test Cases'!$B$2:$B$70,A17,'Test Cases'!$L$2:$L$70,"Pass") -> 3 | E17: =COUNTIFS('Test Cases'!$B$2:$B$70,A17,'Test Cases'!$L$2:$L$70,"Fail") -> 0
A18: Cancel | B18: =COUNTIF('Test Cases'!$B$2:$B$70,A18) -> 5 | C18: =COUNTIFS('Test Cases'!$B$2:$B$70,A18,'Test Cases'!$K$2:$K$70,"High") -> 4 | D18: =COUNTIFS('Test Cases'!$B$2:$B$70,A18,'Test Cases'!$L$2:$L$70,"Pass") -> 3 | E18: =COUNTIFS('Test Cases'!$B$2:$B$70,A18,'Test Cases'!$L$2:$L$70,"Fail") -> 1
A19: Replace | B19: =COUNTIF('Test Cases'!$B$2:$B$70,A19) -> 3 | C19: =COUNTIFS('Test Cases'!$B$2:$B$70,A19,'Test Cases'!$K$2:$K$70,"High") -> 2 | D19: =COUNTIFS('Test Cases'!$B$2:$B$70,A19,'Test Cases'!$L$2:$L$70,"Pass") -> 2 | E19: =COUNTIFS('Test Cases'!$B$2:$B$70,A19,'Test Cases'!$L$2:$L$70,"Fail") -> 1
A20: Approve | B20: =COUNTIF('Test Cases'!$B$2:$B$70,A20) -> 6 | C20: =COUNTIFS('Test Cases'!$B$2:$B$70,A20,'Test Cases'!$K$2:$K$70,"High") -> 3 | D20: =COUNTIFS('Test Cases'!$B$2:$B$70,A20,'Test Cases'!$L$2:$L$70,"Pass") -> 2 | E20: =COUNTIFS('Test Cases'!$B$2:$B$70,A20,'Test Cases'!$L$2:$L$70,"Fail") -> 2
A21: Access | B21: =COUNTIF('Test Cases'!$B$2:$B$70,A21) -> 3 | C21: =COUNTIFS('Test Cases'!$B$2:$B$70,A21,'Test Cases'!$K$2:$K$70,"High") -> 3 | D21: =COUNTIFS('Test Cases'!$B$2:$B$70,A21,'Test Cases'!$L$2:$L$70,"Pass") -> 2 | E21: =COUNTIFS('Test Cases'!$B$2:$B$70,A21,'Test Cases'!$L$2:$L$70,"Fail") -> 0
A22: Export | B22: =COUNTIF('Test Cases'!$B$2:$B$70,A22) -> 5 | C22: =COUNTIFS('Test Cases'!$B$2:$B$70,A22,'Test Cases'!$K$2:$K$70,"High") -> 4 | D22: =COUNTIFS('Test Cases'!$B$2:$B$70,A22,'Test Cases'!$L$2:$L$70,"Pass") -> 4 | E22: =COUNTIFS('Test Cases'!$B$2:$B$70,A22,'Test Cases'!$L$2:$L$70,"Fail") -> 1
A23: Mandatory fields | B23: =COUNTIF('Test Cases'!$B$2:$B$70,A23) -> 6 | C23: =COUNTIFS('Test Cases'!$B$2:$B$70,A23,'Test Cases'!$K$2:$K$70,"High") -> 5 | D23: =COUNTIFS('Test Cases'!$B$2:$B$70,A23,'Test Cases'!$L$2:$L$70,"Pass") -> 4 | E23: =COUNTIFS('Test Cases'!$B$2:$B$70,A23,'Test Cases'!$L$2:$L$70,"Fail") -> 2
A24: Total | B24: =SUM(B12:B23) -> 69 | C24: =SUM(C12:C23) -> 47 | D24: =SUM(D12:D23) -> 54 | E24: =SUM(E12:E23) -> 11
A26: By type | B26: Test cases
A27: Navigation | B27: =COUNTIF('Test Cases'!$J$2:$J$70,A27) -> 4
A28: UI | B28: =COUNTIF('Test Cases'!$J$2:$J$70,A28) -> 5
A29: Functional | B29: =COUNTIF('Test Cases'!$J$2:$J$70,A29) -> 34
A30: Negative | B30: =COUNTIF('Test Cases'!$J$2:$J$70,A30) -> 15
A31: Data | B31: =COUNTIF('Test Cases'!$J$2:$J$70,A31) -> 7
A32: Security | B32: =COUNTIF('Test Cases'!$J$2:$J$70,A32) -> 4
A34: By priority | B34: Test cases
A35: High | B35: =COUNTIF('Test Cases'!$K$2:$K$70,A35) -> 47
A36: Medium | B36: =COUNTIF('Test Cases'!$K$2:$K$70,A36) -> 20
A37: Low | B37: =COUNTIF('Test Cases'!$K$2:$K$70,A37) -> 2
A39: Execution status | B39: Test cases
A40: Not Started | B40: =COUNTIF('Test Cases'!$L$2:$L$70,A40) -> 0
A41: Pass | B41: =COUNTIF('Test Cases'!$L$2:$L$70,A41) -> 54
A42: Fail | B42: =COUNTIF('Test Cases'!$L$2:$L$70,A42) -> 11
A43: Blocked | B43: =COUNTIF('Test Cases'!$L$2:$L$70,A43) -> 4
A44: Not Applicable | B44: =COUNTIF('Test Cases'!$L$2:$L$70,A44) -> 0
A46: Observations | B46: =COUNTA(Observations!$A$2:$A$14) -> 13

Sheet Test Cases
A1: TC ID | B1: Area | C1: Component | D1: Test Case | E1: Preconditions | F1: Test Steps | G1: Test Data | H1: Expected Result | I1: Observed (automated run, build v1.0 1910-49) | J1: Type | K1: Priority | L1: Status | M1: Remarks | N1: Automated in
A2: UR-001 | B2: List & cards | C2: Navigation | D2: Reservations opens from the side menu | E2: Logged in as CRM Administrator | F2: 1. Open Home / Dashboard (/) 2. Click "Reservations" in the main menu | H2: URL is /reservations; eyebrow "RESERVATIONS", heading "Unit Reservations"; the menu item is highlighted | I2: As expected | J2: Navigation | K2: High | L2: Pass | N2: tests/reservations/view.spec.ts
A3: UR-002 | B3: List & cards | C3: Register | D3: Register loads without errors and shows every column | E3: Logged in as CRM Administrator | F3: 1. Open /reservations 2. Look at the Reservation Register 3. Check the browser console and network log | H3: Columns Reservation, Customer, Unit, Status, Date, Amount, Created Date; every row shows an RSV-… number with its OPP-… number; no JavaScript errors, failed API calls, NaN or undefined | I3: As expected | J3: UI | K3: High | L3: Pass | N3: tests/reservations/view.spec.ts
A4: UR-003 | B4: List & cards | C4: KPI cards | D4: Cards show loaded values | E4: Logged in as CRM Administrator | F4: 1. Open /reservations 2. Read All Reservations, Active, Converted, Cancelled and Amount, and the "All amounts in" label | H4: Every card shows a value (not blank or —); Amount is in the base currency named in "All amounts in"; "All Reservations" is selected by default | I4: As expected | J4: UI | K4: Medium | L4: Pass | N4: tests/reservations/view.spec.ts
A5: UR-004 | B5: List & cards | C5: KPI cards | D5: Every reservation is counted in one status card | E5: Logged in as CRM Administrator | F5: 1. Open /reservations 2. Note All Reservations, Active, Converted and Cancelled | H5: All Reservations = Active + Converted + Cancelled (every reservation, including Requested and Superseded ones, falls in one of the status cards) | I5: All Reservations 120, but Active 29 + Converted 82 + Cancelled 7 = 118: Requested and Superseded reservations are in no card (OBS-01) | J5: Data | K5: High | L5: Fail | N5: tests/reservations/view.spec.ts
A6: UR-005 | B6: List & cards | C6: KPI cards | D6: Status cards filter the register | E6: Logged in as CRM Administrator | F6: 1. Open /reservations 2. Click Active, then Converted, then Cancelled, then All Reservations 3. Each time read the pager total and the Status column | H6: The clicked card is pressed; the pager total equals the card value; Active lists Approved / Requested reservations, Converted lists "Converted to Contract", Cancelled lists "Cancelled" | I6: As expected | J6: Functional | K6: High | L6: Pass | N6: tests/reservations/view.spec.ts
A7: UR-006 | B7: List & cards | C7: KPI cards | D7: Amount card equals the amounts in the register | E7: Logged in as CRM Administrator | F7: 1. Open /reservations (All Reservations) 2. Add up the Amount column on every page | H7: Amount card = sum of the listed amounts (within each value's display rounding) | I7: As expected | J7: Data | K7: High | L7: Pass | N7: tests/reservations/view.spec.ts
A8: UR-007 | B8: List & cards | C8: Register | D8: Pagination covers every reservation | E8: Logged in as CRM Administrator | F8: 1. Open /reservations; read "Showing 1–20 of N reservations · Page 1 of M" 2. Click Next, then Previous 3. Sort Created Date oldest first and page to the end, counting rows | H8: N = All Reservations; Previous disabled on page 1; Next / Previous move one page; the last page ends at N and Next is disabled there; N rows in all, none repeated | I8: As expected | J8: Functional | K8: High | L8: Pass | N8: tests/reservations/view.spec.ts
A9: UR-008 | B9: List & cards | C9: Register | D9: Viewing does not change data | E9: Logged in as CRM Administrator | F9: 1. Open /reservations with the network log open 2. Click each status card 3. Sort by Amount 4. Open a reservation and close it | H9: No create / update / delete request (POST, PUT, PATCH, DELETE) to reservation, document, approval or opportunity endpoints | I9: As expected | J9: Functional | K9: High | L9: Pass | N9: tests/reservations/view.spec.ts
A10: UR-009 | B10: Search & sort | C10: Search | D10: Search by reservation number | E10: Logged in as CRM Administrator | F10: 1. Open /reservations 2. Note the 3rd row 3. Type its RSV number in "Search reservation, customer, unit" | G10: RSV number of the 3rd row | H10: Exactly that reservation is listed, with the same values as before | I10: As expected | J10: Functional | K10: High | L10: Pass | N10: tests/reservations/search-sort.spec.ts
A11: UR-010 | B11: Search & sort | C11: Search | D11: Search by customer and by unit | E11: Logged in as CRM Administrator | F11: 1. Open /reservations 2. Search the 2nd row's customer 3. Search the 2nd row's unit code | G11: Customer and unit of the 2nd row | H11: Every row matches the term (number, customer or unit) and the 2nd row is among them | I11: As expected | J11: Functional | K11: High | L11: Pass | N11: tests/reservations/search-sort.spec.ts
A12: UR-011 | B12: Search & sort | C12: Search | D12: Search with no match shows an empty register | E12: Logged in as CRM Administrator | F12: 1. Open /reservations 2. Search a term that matches nothing | G12: "zz-no-such-reservation-<timestamp>" | H12: No rows, an empty-state message, and Export disabled | I12: As expected | J12: Negative | K12: Medium | L12: Pass | N12: tests/reservations/search-sort.spec.ts
A13: UR-012 | B13: Search & sort | C13: Search | D13: Clearing the search restores the register | E13: Logged in as CRM Administrator | F13: 1. Open /reservations; note the total and page 1 2. Search the first row's customer 3. Click the clear (×) button | G13: Customer of the first row | H13: The search narrows the list; after clearing, the box is empty and the total and page 1 are as before | I13: As expected | J13: Functional | K13: Medium | L13: Pass | N13: tests/reservations/search-sort.spec.ts
A14: UR-013 | B14: Search & sort | C14: KPI cards | D14: Cards follow the search | E14: Logged in as CRM Administrator | F14: 1. Open /reservations 2. Search one reservation number 3. Read the cards | G14: RSV number of the first row | H14: All Reservations = 1 and Amount = that reservation's amount; the status card for its status shows 1 | I14: As expected | J14: Data | K14: Medium | L14: Pass | N14: tests/reservations/search-sort.spec.ts
A15: UR-014 | B15: Search & sort | C15: Sort | D15: Sort by Amount | E15: Logged in as CRM Administrator | F15: 1. Open /reservations 2. Click the Amount header until it sorts ascending; check page 1 and the start of page 2 3. Repeat for descending | H15: Amount sorts by the USD amount shown, both directions, across pages; the header shows the direction | I15: Descending lists "0 USD" before "0.96M USD": reservations with no amount come first, then amounts are ordered by their unconverted value (124,000,000 KES ≈ 0.96M USD before USD amounts) (OBS-03) | J15: Functional | K15: Medium | L15: Fail | N15: tests/reservations/search-sort.spec.ts
A16: UR-015 | B16: Search & sort | C16: Sort | D16: Sort by Created Date | E16: Logged in as CRM Administrator | F16: 1. Open /reservations 2. Check the default order 3. Sort Created Date ascending | H16: Default is newest first (Created Date ▼); ascending gives oldest first | I16: As expected | J16: Functional | K16: Medium | L16: Pass | N16: tests/reservations/search-sort.spec.ts
A17: UR-016 | B17: Search & sort | C17: Sort | D17: Sort by Date and Reservation number | E17: Logged in as CRM Administrator | F17: 1. Open /reservations 2. Sort Date ascending, then descending 3. Sort Reservation ascending, then descending | H17: Rows follow the reservation date and the RSV number in both directions | I17: As expected | J17: Functional | K17: Low | L17: Pass | N17: tests/reservations/search-sort.spec.ts
A18: UR-017 | B18: Detail | C18: Reservation Detail | D18: Opening a reservation shows its details | E18: Logged in as CRM Administrator | F18: 1. Open /reservations 2. Click the first RSV number 3. Compare the detail with the row and GET /reservations/<id> | H18: Same number, customer, opportunity, unit, project, amount, date, expiry and status as the row and the API; opening it does not modify the record | I18: As expected | J18: Functional | K18: High | L18: Pass | N18: tests/reservations/view.spec.ts
A19: UR-018 | B19: Detail | C19: Reservation Detail | D19: Opportunity and unit links open their records | E19: Logged in as CRM Administrator | F19: 1. Open a reservation 2. Click the OPPORTUNITY number 3. Go back, open it again and click the UNIT code | H19: The opportunity link opens that Opportunity Detail; the unit link opens that unit in Inventory | I19: As expected | J19: Navigation | K19: Medium | L19: Pass | N19: tests/reservations/view.spec.ts
A20: UR-019 | B20: Detail | C20: Reservation Detail | D20: An Approved reservation shows its next steps | E20: Logged in as CRM Administrator | F20: 1. Click the Active card 2. Open the first Approved reservation | G20: First Approved reservation | H20: Status Approved; workflow Requested and Approved Done; ERP SYNC and DEPOSIT RECEIVED shown; actions Cancel Reservation, Replace Reservation and Move to Proposal | I20: As expected | J20: Functional | K20: High | L20: Pass | N20: tests/reservations/view.spec.ts
A21: UR-020 | B21: Detail | C21: Reservation Detail | D21: A Converted reservation can only be cancelled or replaced | E21: Logged in as CRM Administrator | F21: 1. Click the Converted card 2. Open the first reservation | G21: First "Converted to Contract" reservation | H21: Status "Converted to Contract"; every workflow step Done; actions only Cancel Reservation and Replace Reservation; Quick notes say "Required before cancelling." | I21: As expected | J21: Functional | K21: High | L21: Pass | N21: tests/reservations/view.spec.ts
A22: UR-021 | B22: Detail | C22: Reservation Detail | D22: A Cancelled reservation offers no actions | E22: Logged in as CRM Administrator | F22: 1. Click the Cancelled card 2. Open the first reservation | G22: First Cancelled reservation | H22: Status Cancelled; workflow steps On hold; no Cancel, Replace, Approve or Move to Proposal action | I22: As expected | J22: Functional | K22: High | L22: Pass | N22: tests/reservations/view.spec.ts
A23: UR-022 | B23: Detail | C23: History | D23: History lists the changes with user and time | E23: Logged in as CRM Administrator | F23: 1. Open an Approved reservation 2. Read History 3. Click Refresh | H23: The last entry is "Created" with a user and date-time; status changes are listed as "Reservation status Requested → Approved"; Refresh reloads the list | I23: As expected | J23: Functional | K23: Medium | L23: Pass | N23: tests/reservations/view.spec.ts
A24: UR-023 | B24: Detail | C24: Reservation Detail | D24: Record link (?selected=id) opens and keeps the reservation open | E24: Logged in as CRM Administrator | F24: 1. Copy a row's link (/reservations?selected=<id>) 2. Open it 3. Wait 3 seconds | H24: That reservation's detail opens and stays open until closed | I24: As expected | J24: Navigation | K24: High | L24: Pass | N24: tests/reservations/view.spec.ts
A25: UR-024 | B25: Detail | C25: Reservation Detail | D25: Link to a missing reservation shows a message | E25: Logged in as CRM Administrator | F25: 1. Open /reservations?selected=<id that does not exist> | G25: 00000000-0000-0000-0000-000000000000 | H25: A message says the reservation was not found (no endless loading, no silent close) | I25: No "not found" message appears (OBS-08) | J25: Negative | K25: Medium | L25: Fail | N25: tests/reservations/view.spec.ts
A26: UR-025 | B26: Create form | C26: Create Reservation | D26: New Reservation opens the form with defaults | E26: Logged in as CRM Administrator | F26: 1. Open /reservations 2. Click New Reservation | H26: Dialog "Create Reservation" with "Only opportunities at Reservation Ready stage can be reserved."; fields Opportunity *, Unit * (Choose Unit), Amount (USD), Currency = USD (read-only), Expiry = today + 30 days, Remarks; buttons Close and Create Reservation | I26: As expected | J26: UI | K26: High | L26: Pass | N26: tests/reservations/create-form.spec.ts
A27: UR-026 | B27: Create form | C27: Validation | D27: Submitting an empty form is refused | E27: Logged in as CRM Administrator | F27: 1. Open New Reservation 2. Click Create Reservation without filling anything | H27: Notice "Opportunity Required — Select a reservation-ready opportunity."; no request is sent | I27: As expected | J27: Negative | K27: High | L27: Pass | N27: tests/reservations/create-form.spec.ts
A28: UR-027 | B28: Create form | C28: Validation | D28: Only Reservation Ready opportunities are offered | E28: Logged in as CRM Administrator | F28: 1. Open New Reservation 2. Open the Opportunity list 3. Check the stage of the listed opportunities | G28: First 10 options | H28: Every listed opportunity is at stage Reservation Ready | I28: As expected | J28: Data | K28: High | L28: Pass | N28: tests/reservations/create-form.spec.ts
A29: UR-028 | B29: Create form | C29: Validation | D29: A unit is required | E29: Logged in as CRM Administrator | F29: 1. Open New Reservation 2. Choose an opportunity but no unit 3. Click Create Reservation | G29: First listed opportunity | H29: A message asks for the unit; no request is sent | I29: As expected | J29: Negative | K29: High | L29: Pass | N29: tests/reservations/create-form.spec.ts
A30: UR-029 | B30: Create form | C30: Unit picker | D30: Unit picker lists available units and hides units on hold | E30: Logged in as CRM Administrator | F30: 1. Open New Reservation › Choose Unit 2. Read the units and their status 3. Tick "Hide units on hold" | H30: Dialog "Select Available Unit" with filters Project, Type, Bedrooms, View, Min / Max price; each row shows unit, project, type, beds, floor, area, price, status; ticking "Hide units on hold" never adds units | I30: As expected | J30: Functional | K30: Medium | L30: Pass | N30: tests/reservations/create-form.spec.ts
A31: UR-030 | B31: Create form | C31: Create Reservation | D31: Closing the form creates nothing | E31: Logged in as CRM Administrator | F31: 1. Open New Reservation 2. Choose an opportunity 3. Click Close | G31: First listed opportunity | H31: The dialog closes, no request is sent and the register total is unchanged | I31: As expected | J31: Negative | K31: Medium | L31: Pass | N31: tests/reservations/create-form.spec.ts
A32: UR-031 | B32: Create | C32: Preparation | D32: A test opportunity is brought to Reservation Ready | E32: Logged in as CRM Administrator | F32: 1. Leads › Ready to Convert: convert a lead (Move to Opportunity › Convert) 2. Schedule a virtual visit (next month, 15th) 3. Complete the site visit with outcome notes 4. Enter negotiation notes › Continue to Reservation Ready | G32: A Qualified lead picked at random | H32: The opportunity is at Reservation Ready and is offered in New Reservation › Opportunity | I32: As expected | J32: Functional | K32: High | L32: Pass | N32: tests/reservations/lifecycle.spec.ts
A33: UR-032 | B33: Create | C33: Validation | D33: Reservation amount is required | E33: Logged in as CRM Administrator; the test opportunity prepared by UR-031 | F33: 1. Open New Reservation; choose the test opportunity and an available unit 2. Clear Amount (USD) 3. Click Create Reservation | G33: Amount empty | H33: A message asks for the amount; no reservation is created | I33: Saved anyway (201) with no amount; the test cancelled that reservation straight away (OBS-02) | J33: Negative | K33: High | L33: Fail | N33: tests/reservations/lifecycle.spec.ts
A34: UR-033 | B34: Create | C34: Create Reservation | D34: Choosing a unit fills in the amount | E34: Logged in as CRM Administrator; the test opportunity prepared by UR-031 | F34: 1. Open New Reservation; choose the test opportunity 2. Choose Unit › Select an available unit | G34: First available unit | H34: Unit shows the chosen code; Amount (USD) fills in with a value above 0 | I34: As expected | J34: Functional | K34: Medium | L34: Pass | N34: tests/reservations/lifecycle.spec.ts
A35: UR-034 | B35: Create | C35: Create Reservation | D35: Creating a reservation | E35: Logged in as CRM Administrator; the test opportunity prepared by UR-031 | F35: 1. With the test opportunity and unit chosen and the amount filled in, enter Remarks 2. Click Create Reservation 3. Click OK | G35: Remarks "Automated test - Reservations lifecycle" | H35: POST /reservations succeeds; notice "Reservation Created"; the detail shows status Requested, the opportunity, unit, amount, expiry, "Not yet received · 0 USD" and "Not sent (sent on approval)"; workflow Requested In progress | I35: As expected | J35: Functional | K35: High | L35: Pass | N35: tests/reservations/lifecycle.spec.ts
A36: UR-035 | B36: Create | C36: Register | D36: The new reservation is listed and counted | E36: Logged in as CRM Administrator; the reservation created by UR-034 (Requested) | F36: 1. Open /reservations 2. Look at page 1 3. Search the RSV number 4. Compare All Reservations with before | H36: The reservation is on page 1 with status Requested; search finds it; All Reservations +1 | I36: As expected | J36: Data | K36: High | L36: Pass | N36: tests/reservations/lifecycle.spec.ts
A37: UR-036 | B37: Create | C37: Approvals | D37: Pending My Approval lists the new reservation | E37: Logged in as CRM Administrator; the reservation created by UR-034 (Requested) | F37: 1. Open /reservations 2. Read the "Pending My Approval" panel | H37: A row "Approve reservation" with the RSV number, customer, unit, requester and the remarks as reason | I37: As expected | J37: Functional | K37: High | L37: Pass | N37: tests/reservations/lifecycle.spec.ts
A38: UR-037 | B38: Create | C38: Unit picker | D38: A reserved unit is no longer offered as available | E38: Logged in as CRM Administrator; the reservation created by UR-034 (Requested) | F38: 1. Open New Reservation › Choose Unit 2. Find the reserved unit 3. Tick "Hide units on hold" | G38: The reservation's unit | H38: The unit is not shown as Available with Select (and is hidden by "Hide units on hold") | I38: As expected | J38: Negative | K38: High | L38: Pass | N38: tests/reservations/lifecycle.spec.ts
A39: UR-038 | B39: Create | C39: Validation | D39: A second reservation for the same opportunity is refused | E39: Logged in as CRM Administrator; the reservation created by UR-034 (Requested) | F39: 1. Send POST /reservations for the test opportunity with another available unit | G39: Another available unit | H39: Refused (4xx); the opportunity still has one active reservation | I39: As expected | J39: Negative | K39: High | L39: Pass | N39: tests/reservations/lifecycle.spec.ts
A40: UR-039 | B40: Documents | C40: Upload | D40: Upload validation | E40: Logged in as CRM Administrator; the reservation created by UR-034 (Requested) | F40: 1. Open the reservation 2. Click Upload with no file 3. Choose a .txt file and click Upload | G40: notes.txt | H40: "Choose a file to upload." then "Only PDF, JPG and PNG files can be uploaded."; nothing is uploaded | I40: As expected | J40: Negative | K40: Medium | L40: Pass | N40: tests/reservations/lifecycle.spec.ts
...

Sheet Observations
A1: Obs ID | B1: Area | C1: Observation | D1: Expected / Question | E1: Suggested severity | F1: Related TC
A2: OBS-01 | B2: KPI cards | C2: Requested and Superseded reservations are not counted in any status card: All Reservations 120 vs Active 29 + Converted 82 + Cancelled 7 = 118. | D2: Add a Requested (and Superseded) card, or state which statuses each card covers. | E2: Medium | F2: UR-004
A3: OBS-02 | B3: Create | C3: A reservation is saved without an amount: clearing Amount, typing a non-number ("abc"), or clicking Create before it fills in all create the reservation with no amount (201). | D3: Make Amount required (> 0) in the form and the backend. | E3: High | F3: UR-032, UR-067
A4: OBS-03 | B4: Sort | C4: Sorting by Amount does not follow the USD amounts shown (descending lists "0 USD" before "0.96M USD" and "9,595.3 USD" before "0.47M USD"); amounts in KES / AED seem to be sorted on their original value. | D4: Sort on the amount converted to the base currency, as shown. | E4: Medium | F4: UR-014
A5: OBS-04 | B5: Opportunity | C5: After a reservation created on the Reservations page is approved, the opportunity stays "Reservation Ready" ("Moved to Reservation" Up next) and is still offered for a new reservation. | D5: Move the opportunity to "Moved to Reservation" when its reservation is created / approved, and stop offering it. | E5: High | F5: UR-048
A6: OBS-05 | B6: Workflow | C6: On approval, "Moved to Proposal" is shown as Done although no proposal exists and the next step is "Move to Proposal". | D6: Mark it Done only when a proposal is created. | E6: Medium | F6: UR-049
A7: OBS-06 | B7: Cancel | C7: A cancelled reservation still offers "Retry ERP Sync" ("The reservation deposit is waiting to be sent to ERP"). | D7: Do not offer to send a deposit to ERP for a cancelled reservation (or send a cancellation instead). | E7: High | F7: UR-051
A8: OBS-07 | B8: Replace | C8: Replace Reservation opened from the register does not preselect the reservation's opportunity (it was preselected only when the detail opened right after creating the reservation). | D8: Always preselect the opportunity being replaced. | E8: Medium | F8: UR-043
A9: OBS-08 | B9: Detail | C9: A link to a reservation that does not exist (/reservations?selected=<unknown id>) shows no "not found" message. | D9: Tell the user the reservation was not found or is not accessible. | E9: Medium | F9: UR-024
A10: OBS-09 | B10: Remarks | C10: Approval and cancellation notes replace the reservation's Remarks, so the original remarks only survive in History. | D10: Question: keep the original remarks and show notes separately? | E10: Low | F10: UR-046, UR-050
A11: OBS-10 | B11: Unit picker | C11: The Project filter in the unit picker only offers "All projects" (the QA test project is not listed). | D11: List every project that has units. | E11: Low | F11: UR-029
A12: OBS-11 | B12: Export | C12: Export ignores the selected status card: with Cancelled selected (9 listed) the file holds all 124 reservations of every status. The search is respected. | D12: Export the current list with its card filter, as the button says. | E12: Medium | F12: UR-062
... A14: OBS-13 | B14: Create | C14: A negative amount is refused, but the message is technical: "Validation Failed — reservationAmount: Too small: expected number to be >=0". | D14: Show a plain message such as "Amount must be 0 or more" next to the field. | E14: Low | F14: UR-066
