Workbook

Sheet Summary
A1: Sales Reports — Test Cases
A3: Page | B3: https://qa-crm.asquareab.com/reports/sales
A4: Build | B4: v1.0 1610-47
A5: Explored on | B5: 16-Oct-2026 (CRM Administrator, QA data, screenshots)
A6: Scope | B6: Filter bar (period, custom dates, Project, Salesperson, Broker, Campaign, Reset), views, 8 KPI cards, Open Pipeline by Stage, Salesperson Pipeline, Open Opportunities, exports, number matching, data changes, cross-page and non-functional checks
A7: How to use | B7: Fill "Status" (Pass / Fail / Blocked / Not Applicable) and "Remarks" on the Test Cases sheet; counts below update automatically. Type the figures you see into the yellow cells of "Number Reconciliation" to check the numbers.
A8: Note | B8: "Observed" values were read from the 16-Oct-2026 screenshots (Last 12 months, all filters, view All); data changes over time, so re-read figures when executing. Automated page tests SAL-01…SAL-16 (tests/modules/sales-reports.spec.ts) already cover parts of this workbook.
A9: Last run | B9: 16-Oct-2026 12:37, build v1.0 1610-47 — automated (tests/sales-reports): 101 passed, 19 failed, 12 blocked (skipped by design). Defect report: reports/CRM_Defect_Report_2026-10-16_1237.xlsx
A10: By area | B10: Test cases | C10: High | D10: Pass | E10: Fail
A11: General | B11: =COUNTIF('Test Cases'!$B$2:$B$133,A11) | C11: =COUNTIFS('Test Cases'!$B$2:$B$133,A11,'Test Cases'!$K$2:$K$133,"High") | D11: =COUNTIFS('Test Cases'!$B$2:$B$133,A11,'Test Cases'!$L$2:$L$133,"Pass") | E11: =COUNTIFS('Test Cases'!$B$2:$B$133,A11,'Test Cases'!$L$2:$L$133,"Fail")
A12: Views | B12: =COUNTIF('Test Cases'!$B$2:$B$133,A12) | C12: =COUNTIFS('Test Cases'!$B$2:$B$133,A12,'Test Cases'!$K$2:$K$133,"High") | D12: =COUNTIFS('Test Cases'!$B$2:$B$133,A12,'Test Cases'!$L$2:$L$133,"Pass") | E12: =COUNTIFS('Test Cases'!$B$2:$B$133,A12,'Test Cases'!$L$2:$L$133,"Fail")
A13: Period filter | B13: =COUNTIF('Test Cases'!$B$2:$B$133,A13) | C13: =COUNTIFS('Test Cases'!$B$2:$B$133,A13,'Test Cases'!$K$2:$K$133,"High") | D13: =COUNTIFS('Test Cases'!$B$2:$B$133,A13,'Test Cases'!$L$2:$L$133,"Pass") | E13: =COUNTIFS('Test Cases'!$B$2:$B$133,A13,'Test Cases'!$L$2:$L$133,"Fail")
A14: Dropdown filters | B14: =COUNTIF('Test Cases'!$B$2:$B$133,A14) | C14: =COUNTIFS('Test Cases'!$B$2:$B$133,A14,'Test Cases'!$K$2:$K$133,"High") | D14: =COUNTIFS('Test Cases'!$B$2:$B$133,A14,'Test Cases'!$L$2:$L$133,"Pass") | E14: =COUNTIFS('Test Cases'!$B$2:$B$133,A14,'Test Cases'!$L$2:$L$133,"Fail")
A15: Reset filters | B15: =COUNTIF('Test Cases'!$B$2:$B$133,A15) | C15: =COUNTIFS('Test Cases'!$B$2:$B$133,A15,'Test Cases'!$K$2:$K$133,"High") | D15: =COUNTIFS('Test Cases'!$B$2:$B$133,A15,'Test Cases'!$L$2:$L$133,"Pass") | E15: =COUNTIFS('Test Cases'!$B$2:$B$133,A15,'Test Cases'!$L$2:$L$133,"Fail")
A16: KPI cards | B16: =COUNTIF('Test Cases'!$B$2:$B$133,A16) | C16: =COUNTIFS('Test Cases'!$B$2:$B$133,A16,'Test Cases'!$K$2:$K$133,"High") | D16: =COUNTIFS('Test Cases'!$B$2:$B$133,A16,'Test Cases'!$L$2:$L$133,"Pass") | E16: =COUNTIFS('Test Cases'!$B$2:$B$133,A16,'Test Cases'!$L$2:$L$133,"Fail")
A17: Open Pipeline by Stage | B17: =COUNTIF('Test Cases'!$B$2:$B$133,A17) | C17: =COUNTIFS('Test Cases'!$B$2:$B$133,A17,'Test Cases'!$K$2:$K$133,"High") | D17: =COUNTIFS('Test Cases'!$B$2:$B$133,A17,'Test Cases'!$L$2:$L$133,"Pass") | E17: =COUNTIFS('Test Cases'!$B$2:$B$133,A17,'Test Cases'!$L$2:$L$133,"Fail")
A18: Salesperson Pipeline | B18: =COUNTIF('Test Cases'!$B$2:$B$133,A18) | C18: =COUNTIFS('Test Cases'!$B$2:$B$133,A18,'Test Cases'!$K$2:$K$133,"High") | D18: =COUNTIFS('Test Cases'!$B$2:$B$133,A18,'Test Cases'!$L$2:$L$133,"Pass") | E18: =COUNTIFS('Test Cases'!$B$2:$B$133,A18,'Test Cases'!$L$2:$L$133,"Fail")
A19: Open Opportunities | B19: =COUNTIF('Test Cases'!$B$2:$B$133,A19) | C19: =COUNTIFS('Test Cases'!$B$2:$B$133,A19,'Test Cases'!$K$2:$K$133,"High") | D19: =COUNTIFS('Test Cases'!$B$2:$B$133,A19,'Test Cases'!$L$2:$L$133,"Pass") | E19: =COUNTIFS('Test Cases'!$B$2:$B$133,A19,'Test Cases'!$L$2:$L$133,"Fail")
A20: Export | B20: =COUNTIF('Test Cases'!$B$2:$B$133,A20) | C20: =COUNTIFS('Test Cases'!$B$2:$B$133,A20,'Test Cases'!$K$2:$K$133,"High") | D20: =COUNTIFS('Test Cases'!$B$2:$B$133,A20,'Test Cases'!$L$2:$L$133,"Pass") | E20: =COUNTIFS('Test Cases'!$B$2:$B$133,A20,'Test Cases'!$L$2:$L$133,"Fail")
A21: Number matching | B21: =COUNTIF('Test Cases'!$B$2:$B$133,A21) | C21: =COUNTIFS('Test Cases'!$B$2:$B$133,A21,'Test Cases'!$K$2:$K$133,"High") | D21: =COUNTIFS('Test Cases'!$B$2:$B$133,A21,'Test Cases'!$L$2:$L$133,"Pass") | E21: =COUNTIFS('Test Cases'!$B$2:$B$133,A21,'Test Cases'!$L$2:$L$133,"Fail")
A22: Data changes | B22: =COUNTIF('Test Cases'!$B$2:$B$133,A22) | C22: =COUNTIFS('Test Cases'!$B$2:$B$133,A22,'Test Cases'!$K$2:$K$133,"High") | D22: =COUNTIFS('Test Cases'!$B$2:$B$133,A22,'Test Cases'!$L$2:$L$133,"Pass") | E22: =COUNTIFS('Test Cases'!$B$2:$B$133,A22,'Test Cases'!$L$2:$L$133,"Fail")
... A24: Non-functional | B24: =COUNTIF('Test Cases'!$B$2:$B$133,A24) | C24: =COUNTIFS('Test Cases'!$B$2:$B$133,A24,'Test Cases'!$K$2:$K$133,"High") | D24: =COUNTIFS('Test Cases'!$B$2:$B$133,A24,'Test Cases'!$L$2:$L$133,"Pass") | E24: =COUNTIFS('Test Cases'!$B$2:$B$133,A24,'Test Cases'!$L$2:$L$133,"Fail")
A25: Total | B25: =SUM(B11:B24) | C25: =SUM(C11:C24) | D25: =SUM(D11:D24) | E25: =SUM(E11:E24)
A27: By type | B27: Test cases
A28: Navigation | B28: =COUNTIF('Test Cases'!$J$2:$J$133,A28)
A29: UI | B29: =COUNTIF('Test Cases'!$J$2:$J$133,A29)
A30: Security | B30: =COUNTIF('Test Cases'!$J$2:$J$133,A30)
A31: Functional | B31: =COUNTIF('Test Cases'!$J$2:$J$133,A31)
A32: Dropdown | B32: =COUNTIF('Test Cases'!$J$2:$J$133,A32)
A33: Negative | B33: =COUNTIF('Test Cases'!$J$2:$J$133,A33)
A34: Accessibility | B34: =COUNTIF('Test Cases'!$J$2:$J$133,A34)
A35: Data | B35: =COUNTIF('Test Cases'!$J$2:$J$133,A35)
A36: Non-functional | B36: =COUNTIF('Test Cases'!$J$2:$J$133,A36)
A38: By priority | B38: Test cases
A39: High | B39: =COUNTIF('Test Cases'!$K$2:$K$133,A39)
A40: Medium | B40: =COUNTIF('Test Cases'!$K$2:$K$133,A40)
A41: Low | B41: =COUNTIF('Test Cases'!$K$2:$K$133,A41)
A43: Execution status | B43: Test cases
A44: Not Started | B44: =COUNTIF('Test Cases'!$L$2:$L$133,A44)
A45: Pass | B45: =COUNTIF('Test Cases'!$L$2:$L$133,A45)
...

Sheet Test Cases
A1: TC ID | B1: Area | C1: Component | D1: Test Case | E1: Preconditions | F1: Test Steps | G1: Test Data | H1: Expected Result | I1: Observed (16-Oct-2026 screenshots, build v1.0 1610-47) | J1: Type | K1: Priority | L1: Status | M1: Remarks
A2: SR-001 | B2: General | C2: Navigation | D2: Open Sales Reports from the Reports & Analytics hub card | E2: Logged in as CRM Administrator | F2: 1. Open /reports-analytics 2. Click the "Sales Reports" card (LIVE) | H2: URL is /reports/sales; breadcrumb "REPORTS & ANALYTICS"; heading "Sales Reports"; Sales tab is active | I2: As expected | J2: Navigation | K2: High | L2: Pass | M2: [Run 16-Oct-2026 12:37, build v1.0 1610-47] Passed
A3: SR-002 | B3: General | C3: Navigation | D3: Open Sales Reports directly by URL | E3: Logged in as CRM Administrator | F3: 1. Enter https://qa-crm.asquareab.com/reports/sales in the browser | H3: Page loads with the filter bar, 8 KPI cards and the 3 panels; no error message | I3: As expected | J3: Navigation | K3: High | L3: Pass | M3: [Run 16-Oct-2026 12:37, build v1.0 1610-47] Passed
A4: SR-003 | B4: General | C4: Breadcrumb | D4: "REPORTS & ANALYTICS" breadcrumb returns to the hub | E4: Logged in as CRM Administrator; Sales Reports open (https://qa-crm.asquareab.com/reports/sales) | F4: 1. Click "REPORTS & ANALYTICS" above the heading | H4: Reports & Analytics hub (/reports-analytics) opens | I4: To verify | J4: Navigation | K4: Medium | L4: Pass | M4: [Run 16-Oct-2026 12:37, build v1.0 1610-47] Passed
A5: SR-004 | B5: General | C5: Module tab bar | D5: Module tab bar lists every report and highlights Sales | E5: Logged in as CRM Administrator; Sales Reports open (https://qa-crm.asquareab.com/reports/sales) | F5: 1. Read the tab bar under the intro text | H5: Tabs in order: Sales, Inventory, Customers, Brokers, Marketing, Reservations, SPA, Collections, Exceptions, Leads; Sales is highlighted (dark) | I5: As expected | J5: UI | K5: Medium | L5: Pass | M5: [Run 16-Oct-2026 12:37, build v1.0 1610-47] Passed
A6: SR-005 | B6: General | C6: Module tab bar | D6: Switching module tabs opens the other report and back | E6: Logged in as CRM Administrator; Sales Reports open (https://qa-crm.asquareab.com/reports/sales) | F6: 1. Click "Inventory" 2. Click "Sales" | H6: Step 1 opens /reports/inventory with Inventory highlighted; step 2 returns to /reports/sales with Sales highlighted and valid figures | I6: To verify | J6: Navigation | K6: Medium | L6: Pass | M6: [Run 16-Oct-2026 12:37, build v1.0 1610-47] Passed
A7: SR-006 | B7: General | C7: Layout | D7: Page layout shows every section in order | E7: Logged in as CRM Administrator; Sales Reports open (https://qa-crm.asquareab.com/reports/sales) | F7: 1. Scroll the page from top to bottom | H7: Intro "Open pipeline by stage and salesperson, weighted forecast, win rate and opportunities past their close date. Values in base currency."; filter bar (Period (won / lost), Project, Salesperson, Broker, Campaign, Reset filters); 8 KPI cards; panels Open Pipeline by Stage, Salesperson Pipeline, Open Opportunities, each with an Export button | I7: As expected | J7: UI | K7: High | L7: Pass | M7: [Run 16-Oct-2026 12:37, build v1.0 1610-47] Passed
A8: SR-007 | B8: General | C8: KPI cards | D8: KPI labels and captions | E8: Logged in as CRM Administrator; Sales Reports open (https://qa-crm.asquareab.com/reports/sales) | F8: 1. Read every KPI card | H8: Open opportunities; Pipeline value "Budget of open opportunities"; Weighted pipeline "Value × probability"; Won in period "SPA signed in the period"; Won value; Win rate "Won ÷ (won + lost) in the period"; Average days to win; Past expected close | I8: As expected | J8: UI | K8: Medium | L8: Pass | M8: [Run 16-Oct-2026 12:37, build v1.0 1610-47] Passed
A9: SR-008 | B9: General | C9: Panels | D9: Panel captions explain which figures follow the period | E9: Logged in as CRM Administrator; Sales Reports open (https://qa-crm.asquareab.com/reports/sales) | F9: 1. Read the caption under each panel heading | H9: Open Pipeline by Stage: "Open opportunities today. The period does not apply."; Salesperson Pipeline: "Open figures are as of today; won and lost are for the selected period."; Open Opportunities: "Sorted by expected close date." | I9: As expected | J9: UI | K9: Low | L9: Pass | M9: [Run 16-Oct-2026 12:37, build v1.0 1610-47] Passed
A10: SR-009 | B10: General | C10: Loading | D10: KPIs never settle on a placeholder or broken value | E10: Logged in as CRM Administrator | F10: 1. Open https://qa-crm.asquareab.com/reports/sales 2. Watch the KPI cards until loading finishes 3. Reload the page (F5) and watch again | H10: While loading, a placeholder ("—") may appear briefly; once loaded every KPI shows a real value; no NaN, undefined, blank or Infinity anywhere on the page | I10: To verify | J10: UI | K10: Medium | L10: Pass | M10: [Run 16-Oct-2026 12:37, build v1.0 1610-47] Passed
A11: SR-010 | B11: General | C11: Access | D11: Signed-out user cannot open the report | E11: Signed out (no session) | F11: 1. Enter https://qa-crm.asquareab.com/reports/sales in a private window | H11: Login page is shown; after login the user lands on Sales Reports (or the dashboard); no report data is shown before login | I11: To verify | J11: Security | K11: High | L11: Pass | M11: [Run 16-Oct-2026 12:37, build v1.0 1610-47] Passed
A12: SR-011 | B12: General | C12: Access | D12: User without the Reports right cannot see the report | E12: A user without Reports & Analytics permission | F12: 1. Log in as that user 2. Enter https://qa-crm.asquareab.com/reports/sales | H12: Access denied / not-found page or redirect; Sales Reports card is not on the hub; no data is returned by the API | I12: To verify | J12: Security | K12: High | L12: Blocked | M12: [Run 16-Oct-2026 12:37, build v1.0 1610-47] Skipped: Needs a user without the Reports & Analytics permission (set one up and run manually) Needs a restricted account
A13: SR-012 | B13: Views | C13: View buttons | D13: View buttons All / You and your team / Mine | E13: Logged in as CRM Administrator; Sales Reports open (https://qa-crm.asquareab.com/reports/sales) | F13: 1. Read the buttons next to the heading | H13: Three buttons: All, You and your team, Mine; "All" is active for the CRM Administrator | I13: As expected (All active) | J13: UI | K13: High | L13: Pass | M13: [Run 16-Oct-2026 12:37, build v1.0 1610-47] Passed
... A19: SR-018 | B19: Period filter | C19: Period dropdown | D19: Default period is "This month" | E19: Logged in as CRM Administrator | F19: 1. Open https://qa-crm.asquareab.com/reports/sales | H19: "This month" is selected (same period as the hub and dashboard; workbook scenario RA-013) | I19: "Last 12 months" is selected (see OBS-01) | J19: Dropdown | K19: High | L19: Fail | M19: [Run 16-Oct-2026 12:37, build v1.0 1610-47] Error: Default period expect(received).toBe(expected) // Object.is equality Expected: "this_month" Received: "last_12_months" (see OBS-01)
A20: SR-019 | B20: Period filter | C20: Period dropdown | D20: Each period reloads the report with valid values | E20: Logged in as CRM Administrator; Sales Reports open (https://qa-crm.asquareab.com/reports/sales) | F20: 1. Select each period in turn except Custom dates 2. After each one, read all KPIs and tables | G20: This month … Last 12 months | H20: Selected option stays shown; report reloads (API ?period=<value>); every KPI and table shows valid values, no NaN/blank | I20: To verify | J20: Dropdown | K20: High | L20: Pass | M20: [Run 16-Oct-2026 12:37, build v1.0 1610-47] Passed
A21: SR-020 | B21: Period filter | C21: Period scope | D21: The period changes only won / lost figures | E21: Logged in as CRM Administrator; Sales Reports open (https://qa-crm.asquareab.com/reports/sales); Period = Last 12 months; all filters on "All …"; view = All | F21: 1. Note every KPI and all three tables 2. Select "This month" 3. Compare | G21: Last 12 months → This month | H21: CHANGE: Won in period, Won value, Win rate, Average days to win, and Salesperson Pipeline Won / Won Value / Lost / Win %. UNCHANGED: Open opportunities, Pipeline value, Weighted pipeline, Past expected close, the whole Open Pipeline by Stage table, Salesperson Open / Pipeline / Weighted, the Open Opportunities list | I21: To verify | J21: Functional | K21: High | L21: Pass | M21: [Run 16-Oct-2026 12:37, build v1.0 1610-47] Passed
A22: SR-021 | B22: Period filter | C22: Custom dates | D22: Custom dates shows From and To fields | E22: Logged in as CRM Administrator; Sales Reports open (https://qa-crm.asquareab.com/reports/sales) | F22: 1. Select "Custom dates" 2. Select "Last month" | H22: Step 1: From and To date fields appear; step 2: the fields disappear and Last month figures load | I22: To verify | J22: Dropdown | K22: Medium | L22: Pass | M22: [Run 16-Oct-2026 12:37, build v1.0 1610-47] Passed
A23: SR-022 | B23: Period filter | C23: Custom dates | D23: A valid custom range reloads the report | E23: Logged in as CRM Administrator; Sales Reports open (https://qa-crm.asquareab.com/reports/sales) | F23: 1. Select "Custom dates" 2. From = 01-Sep-2026, To = 30-Sep-2026 | G23: 01-Sep-2026 → 30-Sep-2026 | H23: Report reloads (API period=custom&from=2026-09-01&to=2026-09-30); won/lost figures are for September only | I23: To verify | J23: Functional | K23: High | L23: Pass | M23: [Run 16-Oct-2026 12:37, build v1.0 1610-47] Passed
A24: SR-023 | B24: Period filter | C24: Custom dates | D24: From later than To is rejected with a message | E24: Logged in as CRM Administrator; Sales Reports open (https://qa-crm.asquareab.com/reports/sales) | F24: 1. Select "Custom dates" 2. From = 30-Sep-2026, To = 01-Sep-2026 | G24: 30-Sep-2026 → 01-Sep-2026 | H24: A validation message is shown; the report is not reloaded with an invalid range | I24: To verify | J24: Negative | K24: Medium | L24: Fail | M24: [Run 16-Oct-2026 12:37, build v1.0 1610-47] Error: Validation message expect(locator).toBeVisible() failed Locator: locator('//main//section[contains(@class,\'crm-panel\')][.//select]').first().getByText(/before|after|invalid|must be|cannot be|earlier|later/i).first() Expected: visible (see OBS-17) Lead Reports shows no message here (Lead OBS-02)
A25: SR-024 | B25: Period filter | C25: Custom dates | D25: Only one date entered does not reload the report | E25: Logged in as CRM Administrator; Sales Reports open (https://qa-crm.asquareab.com/reports/sales) | F25: 1. Select "Custom dates" 2. Enter only From = 01-Sep-2026 | H25: No request with an incomplete range; figures stay unchanged until both dates are valid (or a hint asks for To) | I25: To verify | J25: Negative | K25: Low | L25: Pass | M25: [Run 16-Oct-2026 12:37, build v1.0 1610-47] Passed
A26: SR-025 | B26: Period filter | C26: Custom dates | D26: Future range shows zero won / lost, open figures unchanged | E26: Logged in as CRM Administrator; Sales Reports open (https://qa-crm.asquareab.com/reports/sales); Period = Last 12 months; all filters on "All …"; view = All | F26: 1. Select "Custom dates" 2. From = 01-Jan-2027, To = 31-Jan-2027 | G26: 01-Jan-2027 → 31-Jan-2027 | H26: Won in period 0; Won value 0 USD; Win rate "—"; Average days to win "—"; Salesperson Won/Lost 0, Win % "—"; Open opportunities, Pipeline, Weighted, Past expected close and the stage table unchanged | I26: To verify | J26: Negative | K26: Medium | L26: Pass | M26: [Run 16-Oct-2026 12:37, build v1.0 1610-47] Passed
A27: SR-026 | B27: Period filter | C27: Custom dates | D27: Range with no data shows zeros, not NaN | E27: Logged in as CRM Administrator; Sales Reports open (https://qa-crm.asquareab.com/reports/sales) | F27: 1. Select "Custom dates" 2. From = 01-Jan-2000, To = 31-Jan-2000 | G27: 01-Jan-2000 → 31-Jan-2000 | H27: Same as a future range: zeros and "—"; no NaN, undefined or blank values; no error | I27: To verify | J27: Negative | K27: Medium | L27: Pass | M27: [Run 16-Oct-2026 12:37, build v1.0 1610-47] Passed
A28: SR-027 | B28: Period filter | C28: Custom dates | D28: Range boundaries are inclusive | E28: An opportunity won (SPA signed) on a known date D | F28: 1. Select "Custom dates" 2. From = D, To = D | G28: From = To = D | H28: Won in period ≥ 1 and includes the SPA signed on D; Won value includes its value | I28: To verify | J28: Functional | K28: Medium | L28: Pass | M28: [Run 16-Oct-2026 12:37, build v1.0 1610-47] Passed
A29: SR-028 | B29: Period filter | C29: Period dropdown | D29: Period dropdown works from the keyboard | E29: Logged in as CRM Administrator; Sales Reports open (https://qa-crm.asquareab.com/reports/sales) | F29: 1. Tab to the Period dropdown 2. Use arrow keys to choose "Last month" 3. Press Enter / Tab away | H29: Focus is visible; the selection changes and the report reloads for Last month | I29: To verify | J29: Accessibility | K29: Low | L29: Pass | M29: [Run 16-Oct-2026 12:37, build v1.0 1610-47] Passed
A30: SR-029 | B30: Dropdown filters | C30: Project dropdown | D30: "Project" dropdown label and default | E30: Logged in as CRM Administrator; Sales Reports open (https://qa-crm.asquareab.com/reports/sales) | F30: 1. Read the "Project" dropdown | H30: Label "Project"; "All projects" is the first option and is selected by default | I30: As expected | J30: Dropdown | K30: High | L30: Pass | M30: [Run 16-Oct-2026 12:37, build v1.0 1610-47] Passed
A31: SR-030 | B31: Dropdown filters | C31: Project dropdown | D31: "Project" options match the master data | E31: Logged in as CRM Administrator; Sales Reports open (https://qa-crm.asquareab.com/reports/sales) | F31: 1. Open the "Project" dropdown 2. Compare the options with the source list | G31: Source: the project master (Projects / Inventory Reports › Inventory by Project) | H31: Every project from the source appears exactly once; no blank, duplicate, "undefined" or deleted / inactive entries; options sorted A→Z after "All projects" | I31: To verify | J31: Dropdown | K31: Medium | L31: Pass | M31: [Run 16-Oct-2026 12:37, build v1.0 1610-47] Passed
A32: SR-031 | B32: Dropdown filters | C32: Project dropdown | D32: "Project" filter narrows the report | E32: Logged in as CRM Administrator; Sales Reports open (https://qa-crm.asquareab.com/reports/sales); Period = Last 12 months; all filters on "All …"; view = All | F32: 1. Note all KPIs 2. Select a project from the dropdown 3. Read KPIs and tables 4. Open 2–3 rows of Open Opportunities and check the record | H32: Report reloads for that project only; every count and amount ≤ unfiltered; every Open Opportunities row belongs to that project | I32: To verify | J32: Functional | K32: High | L32: Pass | M32: [Run 16-Oct-2026 12:37, build v1.0 1610-47] Passed
A33: SR-032 | B33: Dropdown filters | C33: Salesperson dropdown | D33: "Salesperson" dropdown label and default | E33: Logged in as CRM Administrator; Sales Reports open (https://qa-crm.asquareab.com/reports/sales) | F33: 1. Read the "Salesperson" dropdown | H33: Label "Salesperson"; "All salespeople" is the first option and is selected by default | I33: As expected | J33: Dropdown | K33: High | L33: Pass | M33: [Run 16-Oct-2026 12:37, build v1.0 1610-47] Passed
A34: SR-033 | B34: Dropdown filters | C34: Salesperson dropdown | D34: "Salesperson" options match the master data | E34: Logged in as CRM Administrator; Sales Reports open (https://qa-crm.asquareab.com/reports/sales) | F34: 1. Open the "Salesperson" dropdown 2. Compare the options with the source list | G34: Source: active sales users; must include every name in Salesperson Pipeline (CRM Administrator, QA Lead Reviewer, QA Sales Manager, Mahalakshmi) | H34: Every salesperson from the source appears exactly once; no blank, duplicate, "undefined" or deleted / inactive entries; options sorted A→Z after "All salespeople" | I34: To verify | J34: Dropdown | K34: Medium | L34: Pass | M34: [Run 16-Oct-2026 12:37, build v1.0 1610-47] Passed
A35: SR-034 | B35: Dropdown filters | C35: Salesperson dropdown | D35: "Salesperson" filter narrows the report | E35: Logged in as CRM Administrator; Sales Reports open (https://qa-crm.asquareab.com/reports/sales); Period = Last 12 months; all filters on "All …"; view = All | F35: 1. Note all KPIs 2. Select a salesperson from the dropdown 3. Read KPIs and tables 4. Open 2–3 rows of Open Opportunities and check the record | H35: Report reloads for that salesperson only; every count and amount ≤ unfiltered; every Open Opportunities row belongs to that salesperson | I35: To verify | J35: Functional | K35: High | L35: Pass | M35: [Run 16-Oct-2026 12:37, build v1.0 1610-47] Passed
A36: SR-035 | B36: Dropdown filters | C36: Broker dropdown | D36: "Broker" dropdown label and default | E36: Logged in as CRM Administrator; Sales Reports open (https://qa-crm.asquareab.com/reports/sales) | F36: 1. Read the "Broker" dropdown | H36: Label "Broker"; "All brokers" is the first option and is selected by default | I36: As expected | J36: Dropdown | K36: High | L36: Pass | M36: [Run 16-Oct-2026 12:37, build v1.0 1610-47] Passed
A37: SR-036 | B37: Dropdown filters | C37: Broker dropdown | D37: "Broker" options match the master data | E37: Logged in as CRM Administrator; Sales Reports open (https://qa-crm.asquareab.com/reports/sales) | F37: 1. Open the "Broker" dropdown 2. Compare the options with the source list | G37: Source: active brokers (Broker Reports › Broker Performance) | H37: Every broker from the source appears exactly once; no blank, duplicate, "undefined" or deleted / inactive entries; options sorted A→Z after "All brokers" | I37: To verify | J37: Dropdown | K37: Medium | L37: Fail | M37: [Run 16-Oct-2026 12:37, build v1.0 1610-47] Error: Every source entry is offered expect(received).toEqual(expected) // deep equality - Expected - 1 + Received + 4 (see OBS-16)
A38: SR-037 | B38: Dropdown filters | C38: Broker dropdown | D38: "Broker" filter narrows the report | E38: Logged in as CRM Administrator; Sales Reports open (https://qa-crm.asquareab.com/reports/sales); Period = Last 12 months; all filters on "All …"; view = All | F38: 1. Note all KPIs 2. Select a broker from the dropdown 3. Read KPIs and tables 4. Open 2–3 rows of Open Opportunities and check the record | H38: Report reloads for that broker only; every count and amount ≤ unfiltered; every Open Opportunities row belongs to that broker | I38: To verify | J38: Functional | K38: High | L38: Pass | M38: [Run 16-Oct-2026 12:37, build v1.0 1610-47] Passed
A39: SR-038 | B39: Dropdown filters | C39: Campaign dropdown | D39: "Campaign" dropdown label and default | E39: Logged in as CRM Administrator; Sales Reports open (https://qa-crm.asquareab.com/reports/sales) | F39: 1. Read the "Campaign" dropdown | H39: Label "Campaign"; "All campaigns" is the first option and is selected by default | I39: As expected | J39: Dropdown | K39: High | L39: Pass | M39: [Run 16-Oct-2026 12:37, build v1.0 1610-47] Passed
A40: SR-039 | B40: Dropdown filters | C40: Campaign dropdown | D40: "Campaign" options match the master data | E40: Logged in as CRM Administrator; Sales Reports open (https://qa-crm.asquareab.com/reports/sales) | F40: 1. Open the "Campaign" dropdown 2. Compare the options with the source list | G40: Source: campaigns (Marketing Reports › Campaign Performance) | H40: Every campaign from the source appears exactly once; no blank, duplicate, "undefined" or deleted / inactive entries; options sorted A→Z after "All campaigns" | I40: To verify | J40: Dropdown | K40: Medium | L40: Pass | M40: [Run 16-Oct-2026 12:37, build v1.0 1610-47] Passed
A41: SR-040 | B41: Dropdown filters | C41: Campaign dropdown | D41: "Campaign" filter narrows the report | E41: Logged in as CRM Administrator; Sales Reports open (https://qa-crm.asquareab.com/reports/sales); Period = Last 12 months; all filters on "All …"; view = All | F41: 1. Note all KPIs 2. Select a campaign from the dropdown 3. Read KPIs and tables 4. Open 2–3 rows of Open Opportunities and check the record | H41: Report reloads for that campaign only; every count and amount ≤ unfiltered; every Open Opportunities row belongs to that campaign | I41: To verify | J41: Functional | K41: High | L41: Pass | M41: [Run 16-Oct-2026 12:37, build v1.0 1610-47] Passed
A42: SR-041 | B42: Dropdown filters | C42: Salesperson dropdown | D42: Salespeople with the same name can be told apart | E42: Logged in as CRM Administrator; Sales Reports open (https://qa-crm.asquareab.com/reports/sales) | F42: 1. Open the "Salesperson" dropdown 2. Look for repeated names 3. Select each one | H42: Same-name users are distinguishable (e.g. email or code shown); each option filters to that user only | I42: To verify | J42: Dropdown | K42: Medium | L42: Fail | M42: [Run 16-Oct-2026 12:37, build v1.0 1610-47] Error: Salesperson options that look the same expect(received).toEqual(expected) // deep equality - Expected - 1 + Received + 3 (see OBS-15) Lead Reports lists "Mahalakshmi" twice (Lead OBS-06)
A43: SR-042 | B43: Dropdown filters | C43: Salesperson dropdown | D43: Salesperson with only a won deal (no open opportunities) | E43: Logged in as CRM Administrator; Sales Reports open (https://qa-crm.asquareab.com/reports/sales); Period = Last 12 months; all filters on "All …"; view = All | F43: 1. Select Salesperson = Mahalakshmi | G43: Mahalakshmi | H43: Open opportunities 0; Pipeline 0 USD; Weighted 0 USD; Past expected close 0; stage table and Open Opportunities show the empty-state message; Won in period, Won value and Win rate equal Mahalakshmi's row in the unfiltered Salesperson Pipeline (1, 1.33M USD, 100%) | I43: To verify | J43: Functional | K43: Medium | L43: Pass | M43: [Run 16-Oct-2026 12:37, build v1.0 1610-47] Passed
A44: SR-043 | B44: Dropdown filters | C44: Project dropdown | D44: Project with no opportunities shows zeros and empty tables | E44: Logged in as CRM Administrator; Sales Reports open (https://qa-crm.asquareab.com/reports/sales) | F44: 1. Select a project that has no opportunities | H44: All counts 0, amounts 0 USD, Win rate and Average days to win "—"; tables show an empty-state message (not a blank grid); no error | I44: To verify | J44: Negative | K44: Medium | L44: Pass | M44: [Run 16-Oct-2026 12:37, build v1.0 1610-47] Passed
A45: SR-044 | B45: Dropdown filters | C45: Combination | D45: Two filters combine (AND) | E45: Logged in as CRM Administrator; Sales Reports open (https://qa-crm.asquareab.com/reports/sales); Period = Last 12 months; all filters on "All …"; view = All | F45: 1. Select a Project; note Open opportunities 2. Reset; select a Salesperson; note it 3. Select both together | H45: Combined result ≤ each filter alone; every Open Opportunities row matches both the project and the salesperson | I45: To verify | J45: Functional | K45: High | L45: Pass | M45: [Run 16-Oct-2026 12:37, build v1.0 1610-47] Passed
...

Sheet Number Reconciliation
A1: Sales Reports — Number Reconciliation
A2: Yellow cells are inputs: type the figures shown on screen (amounts in millions USD, e.g. 2.17B → 2170). Pre-filled with the 16-Oct-2026 screenshots (Last 12 months, all filters, view All). The Checks section recalculates. Amount tolerance 0.5% (display rounding), counts exact.
A4: Inputs — KPI cards
B5: KPI | C5: Value | D5: Unit
B6: Open opportunities | C6: 39 | D6: count
B7: Pipeline value | C7: 2170 | D7: M USD
B8: Weighted pipeline | C8: 1650 | D8: M USD
B9: Won in period | C9: 78 | D9: count
B10: Won value | C10: 149.91 | D10: M USD
B11: Win rate | C11: 97.5 | D11: %
B12: Average days to win | C12: 10 | D12: days
B13: Past expected close | C13: 23 | D13: count
A15: Inputs — Open Pipeline by Stage
B16: Stage | C16: Opportunities | D16: Value (M USD) | E16: Weighted (M USD) | F16: Share of Value % | G16: Implied prob. % | H16: Computed share %
B17: Site Visit | C17: 4 | D17: 115.02 | E17: 103.51 | F17: 5.3 | G17: =IF(D17=0,"—",E17/D17*100) | H17: =IF(SUM($D$17:$D$20)=0,0,D17/SUM($D$17:$D$20)*100)
B18: Negotiation | C18: 4 | D18: 16.42 | E18: 9.85 | F18: 0.8 | G18: =IF(D18=0,"—",E18/D18*100) | H18: =IF(SUM($D$17:$D$20)=0,0,D18/SUM($D$17:$D$20)*100)
B19: Proposal | C19: 1 | D19: 1 | E19: 0.85 | F19: 0 | G19: =IF(D19=0,"—",E19/D19*100) | H19: =IF(SUM($D$17:$D$20)=0,0,D19/SUM($D$17:$D$20)*100)
B20: Reservation Ready | C20: 30 | D20: 2040 | E20: 1530 | F20: 93.9 | G20: =IF(D20=0,"—",E20/D20*100) | H20: =IF(SUM($D$17:$D$20)=0,0,D20/SUM($D$17:$D$20)*100)
B21: Total row (as shown) | C21: 39 | D21: 2170 | E21: 1650 | F21: 100
A23: Inputs — Salesperson Pipeline
B24: Salesperson | C24: Open | D24: Pipeline (M USD) | E24: Weighted (M USD) | F24: Won | G24: Won Value (M USD) | H24: Lost | I24: Win % (shown)
B25: CRM Administrator | C25: 34 | D25: 2170 | E25: 1650 | F25: 76 | G25: 147.42 | H25: 2 | I25: 97.4
B26: QA Lead Reviewer | C26: 4 | D26: 3.24 | E26: 2.1 | F26: 1 | G26: 1.16 | H26: 0 | I26: 100
B27: QA Sales Manager | C27: 1 | D27: 1.5 | E27: 0.9 | F27: 0 | G27: 0 | H27: 0
B28: Mahalakshmi | C28: 0 | D28: 0 | E28: 0 | F28: 1 | G28: 1.33 | H28: 0 | I28: 100
B29: (add rows above if more salespeople)
A31: Inputs — Open Opportunities list (count from screen or the Export file)
B32: Figure | C32: Value
B33: Rows in the list
B34: Σ Value (M USD)
B35: Σ Value × Probability (M USD)
B36: Rows with Expected Close before today
A38: Checks
A39: # | B39: Check | C39: Related TC | D39: Left | E39: Right | F39: Difference | G39: Tolerance | H39: Result
A40: 1 | B40: Open opportunities = Stage Total | C40: SR-082 | D40: =IF(ISBLANK(C6),"",C6) | E40: =IF(ISBLANK(C21),"",C21) | F40: =IF(OR(D40="",E40=""),"",D40-E40) | G40: =0 | H40: =IF(OR(D40="",E40=""),"Not checked",IF(ABS(D40-E40)<=G40+0.000001,"Match","Mismatch"))
A41: 2 | B41: Open opportunities = Σ stage Opportunities | C41: SR-095 | D41: =IF(ISBLANK(C6),"",C6) | E41: =SUM(C17:C20) | F41: =IF(OR(D41="",E41=""),"",D41-E41) | G41: =0 | H41: =IF(OR(D41="",E41=""),"Not checked",IF(ABS(D41-E41)<=G41+0.000001,"Match","Mismatch"))
A42: 3 | B42: Open opportunities = Σ Salesperson Open | C42: SR-083 | D42: =IF(ISBLANK(C6),"",C6) | E42: =SUM(C25:C29) | F42: =IF(OR(D42="",E42=""),"",D42-E42) | G42: =0 | H42: =IF(OR(D42="",E42=""),"Not checked",IF(ABS(D42-E42)<=G42+0.000001,"Match","Mismatch"))
A43: 4 | B43: Open opportunities = rows in list | C43: SR-084 | D43: =IF(ISBLANK(C6),"",C6) | E43: =IF(ISBLANK(C33),"",C33) | F43: =IF(OR(D43="",E43=""),"",D43-E43) | G43: =0 | H43: =IF(OR(D43="",E43=""),"Not checked",IF(ABS(D43-E43)<=G43+0.000001,"Match","Mismatch"))
A44: 5 | B44: Pipeline value = Stage Total Value | C44: SR-087 | D44: =IF(ISBLANK(C7),"",C7) | E44: =IF(ISBLANK(D21),"",D21) | F44: =IF(OR(D44="",E44=""),"",D44-E44) | G44: =ABS(D44)*0.005 | H44: =IF(OR(D44="",E44=""),"Not checked",IF(ABS(D44-E44)<=G44+0.000001,"Match","Mismatch"))
A45: 6 | B45: Pipeline value = Σ stage Value | C45: SR-087 | D45: =IF(ISBLANK(C7),"",C7) | E45: =SUM(D17:D20) | F45: =IF(OR(D45="",E45=""),"",D45-E45) | G45: =ABS(D45)*0.005 | H45: =IF(OR(D45="",E45=""),"Not checked",IF(ABS(D45-E45)<=G45+0.000001,"Match","Mismatch"))
...

Sheet Dropdown Matrix
A1: Dropdown | B1: Label on screen | C1: Default / first option | D1: Options (expected) | E1: Source to compare with | F1: Changes | G1: Does NOT change | H1: Validation rules | I1: Related TCs
A2: Period | B2: Period (won / lost) | C2: This month (observed: Last 12 months) | D2: This month, Last month, This quarter, Last quarter, Year to date, Last 12 months, Custom dates | E2: Same list as every report module (Lead Reports LR-016) | F2: Won in period, Won value, Win rate, Average days to win; Salesperson Won / Won Value / Lost / Win % | G2: Open opportunities, Pipeline value, Weighted pipeline, Past expected close, Open Pipeline by Stage, Salesperson Open / Pipeline / Weighted, Open Opportunities list | H2: Custom dates shows From / To; From ≤ To; both dates needed; boundaries inclusive; empty range shows 0 and "—" | I2: SR-017 … SR-104 (15)
A3: Project | B3: Project | C3: All projects | D3: All projects + every project, A→Z, no duplicates / blanks | E3: Projects master; Inventory Reports › Inventory by Project | F3: Every KPI and all three tables | G3: — | H3: Rows belong to the project; projects add up to the total | I3: SR-029 … SR-043 (4)
A4: Salesperson | B4: Salesperson | C4: All salespeople | D4: All salespeople + every sales user, A→Z, same-name users distinguishable | E4: Users with a sales role; names in Salesperson Pipeline | F4: Every KPI and all three tables | G4: — | H4: Filtered KPIs = that salesperson's row; rows have that salesperson | I4: SR-032 … SR-077 (6)
A5: Broker | B5: Broker | C5: All brokers | D5: All brokers + every active broker, A→Z | E5: Broker Reports › Broker Performance | F5: Every KPI and all three tables | G5: — | H5: Brokers add up to ≤ the total (gap = direct deals) | I5: SR-035 … SR-037 (3)
A6: Campaign | B6: Campaign | C6: All campaigns | D6: All campaigns + every campaign, A→Z | E6: Marketing Reports › Campaign Performance | F6: Every KPI and all three tables | G6: — | H6: Campaigns add up to ≤ the total (gap = no campaign) | I6: SR-038 … SR-040 (3)
A7: View | B7: All / You and your team / Mine | C7: All (admin); team (manager); Mine (salesperson) | D7: All, You and your team, Mine | E7: User role and reporting line | F7: Every KPI and all three tables | G7: — | H7: All ≥ team ≥ Mine; Mine = user's row in All | I7: SR-012 … SR-108 (6)
A8: Reset filters | B8: Reset filters | C8: Disabled | D8: — | E8: — | F8: Period and the four dropdowns back to defaults | G8: View buttons (confirm) | H8: Disabled until something changes | I8: SR-051 … SR-053 (3)

Sheet Observations
A1: Obs ID | B1: Area | C1: Observation | D1: Expected / Question | E1: Suggested severity | F1: Related TC
A2: OBS-01 | B2: Period | C2: The page opens on "Last 12 months". | D2: Should open on "This month" like the hub and dashboard (workbook scenario RA-013; same as Lead OBS-01). | E2: Medium | F2: SR-018
A3: OBS-02 | B3: Open Pipeline by Stage | C3: Stages are listed Site Visit, Negotiation, Proposal, Reservation Ready. The opportunity workflow has no Proposal step, and the Opportunities page lists the stages as Qualified, Site Visit, Negotiation, Reservation Ready, Proposal. | D3: Confirm where Proposal belongs and list stages in that pipeline order. | E3: Low | F3: SR-060
A4: OBS-03 | B4: Open Pipeline by Stage | C4: Proposal has 1M USD of value but Share of Value % shows "0%" (actual 0.05%). | D4: Show "<0.1%" or two decimals so a non-zero stage never reads as 0%. | E4: Low | F4: SR-062
A5: OBS-04 | B5: Weighted pipeline | C5: Weighted ÷ Value per stage: Site Visit 90%, Negotiation 60%, Proposal 85%, Reservation Ready 75%. The earliest stage carries the highest probability, and Reservation Ready averages 75% although its listed rows show 85%. | D5: Confirm the probability comes from each opportunity (not the stage) and that Site Visit deals at ~90% are correct data. | E5: Medium | F5: SR-092
A6: OBS-05 | B6: Open Opportunities | C6: 23 of 39 open opportunities are past their expected close (oldest 17 Jun 2026, 4 months overdue), but overdue rows look the same as the others. | D6: Highlight overdue rows; data owners to update close dates. | E6: Low | F6: SR-073
A7: OBS-06 | B7: Salesperson Pipeline | C7: No Total row, while Open Pipeline by Stage has one. | D7: Add a Total row so the table can be matched against the KPIs at a glance. | E7: Low | F7: SR-067
A8: OBS-07 | B8: Formatting | C8: Amounts drop trailing zeros inconsistently ("1.1M USD", "2.5M USD", "1M USD" next to "1.12M USD", "2.59M USD"). | D8: Use a fixed number of decimals for amounts in one column. | E8: Low | F8: SR-055
A9: OBS-08 | B9: Won in period | C9: Caption says "SPA signed in the period" — Won is defined by SPA signing. | D9: Confirm Won in period / Won value must equal SPA Reports "SPAs signed in period" / "Signed value" for the same period and filters. | E9: Question | F9: SR-123
A10: OBS-09 | B10: Opportunity Detail | C10: Opening OPP-2026-0063 from the list shows EXPECTED CLOSE as "2026-06-17T00:00:00.000Z" (the list shows 17 Jun 2026). | D10: Show the date in the app format (DD Mon YYYY). | E10: Medium | F10: SR-072
A11: OBS-10 | B11: Open opportunities | C11: Sales Reports shows 39 open opportunities; the hub, the Executive Dashboard and the Opportunities page show 43 (the Opportunities page counts Qualified as open; the stage table has no Qualified row). | D11: One definition of "open" everywhere — confirm whether Qualified is part of the pipeline. | E11: High | F11: SR-118
A12: OBS-11 | B12: Pipeline value | C12: Hub shows Pipeline Value 178.94M USD and Weighted Pipeline 153.45M USD; Sales Reports shows 2.17B USD and 1.65B USD. | D12: Same open pipeline on both pages (the hub may be applying "This month" to an as-of-today figure). | E12: High | F12: SR-119
... A21: OBS-20 | B21: Performance | C21: From the test machine: page ready in 4.0 s (target 3 s), Campaign filter reload 3.6 s (target 2 s). | D21: Confirm the targets; measure from the office network. | E21: Low | F21: SR-126
